Workbook

Sheet SOND
B5: SONDAGEM DE ÓLEO DIESEL RAMPART 2500 CLASS
B8: DATA | C8: =NOW() -> 44867.261
B9: HORA | C9: =NOW() -> 44867.261
B10: TRIM | C10: SONDAGEM(MM) | D10: VOLUME(LTS) | E10: % | F10: CAPACIDADE(LTS)
G11: DIFERENÇA
B12: -30
B13: TANQUES
B14: DIÁRIO BB | C14: 1670 | D14: =LOOKUP(C14,DIARIO!A1:A201,DIARIO!B1:B201) -> 6611.5 | E14: =(D14/(F14-I14)) -> 0.87883823 | F14: 7921 | G14: =F14-D14 -> 1309.5 | H14: 1 | I14: =F14-7523 -> 398
B15: DIÁRIO BE | C15: 1670 | D15: =LOOKUP(C15,DIARIO!A2:A202,DIARIO!B2:B202) -> 6611.5 | E15: =(D15/(F15-I15)) -> 0.87883823 | F15: 7921 | G15: =F15-D15 -> 1309.5 | H15: 1 | I15: =F15-7523 -> 398
B16: ARM BB | C16: 1170 | D16: =VLOOKUP(C$16,ARM!A$2:L$133,MATCH(B$12,ARM!A$2:L$2,0)) -> 7079.9 | E16: =(D16/(F16-I16)) -> 0.94600481 | F16: 8314 | G16: =F16-D16 -> 1234.1 | H16: 1 | I16: 830
B17: ARM BE | C17: 1180 | D17: =VLOOKUP(C$17,ARM!A$2:L$133,MATCH(B$12,ARM!A$2:L$2,0)) -> 7168.6 | E17: =(D17/(F17-I17)) -> 0.95785676 | F17: 8314 | G17: =F17-D17 -> 1145.4 | H17: 1 | I17: 830
B18: CTL | C18: 160 | D18: =VLOOKUP(C18,CTL!A2:L133,MATCH(B12,CTL!A2:L2,0)) -> 8432.4 | E18: =(D18/(F18-I18)) -> 0.2389188 | F18: =LOOKUP(B12,CTL!B134:L134,CTL!B133:L133) -> 39112 | G18: =F18-D18 -> 30679.6 | H18: 1 | I18: 3818
B19: TOTAL | D19: =SUM(D14:D18) -> 35903.9 | E19: {=SUM(E14:E18/5)} -> 0.78009137 | F19: =SUM(F14:F18) -> 71582

Sheet CTL
A1: TRIM TQ CENTRAL
A2: ALTURA | B2: -50 | C2: -40 | D2: -30 | E2: -20 | F2: -10 | G2: 0 | H2: 10 | I2: 20 | J2: 30 | K2: 40 | L2: 50
A3: 0 | B3: 5112 | C3: 4618 | D3: 4125 | E3: 3632 | F3: 3147 | G3: 2678 | H3: 2243 | I3: 1852 | J3: 1506 | K3: 1206 | L3: 954
A4: 10 | B4: =((B$13-B$3)/10)+B3 -> 5379.1 | C4: =((C$13-C$3)/10)+C3 -> 4885 | D4: =((D$13-D$3)/10)+D3 -> 4391.7 | E4: =((E$13-E$3)/10)+E3 -> 3898.5 | F4: =((F$13-F$3)/10)+F3 -> 3412.5 | G4: =((G$13-G$3)/10)+G3 -> 2940.9 | H4: =((H$13-H$3)/10)+H3 -> 2500.1 | I4: =((I$13-I$3)/10)+I3 -> 2099.5 | ... L4: =((L$13-L$3)/10)+L3 -> 1157.1
A5: 20 | B5: =((B$13-B$3)/10)+B4 -> 5646.2 | C5: =((C$13-C$3)/10)+C4 -> 5152 | D5: =((D$13-D$3)/10)+D4 -> 4658.4 | E5: =((E$13-E$3)/10)+E4 -> 4165 | F5: =((F$13-F$3)/10)+F4 -> 3678 | G5: =((G$13-G$3)/10)+G4 -> 3203.8 | H5: =((H$13-H$3)/10)+H4 -> 2757.2 | I5: =((I$13-I$3)/10)+I4 -> 2347 | ... L5: =((L$13-L$3)/10)+L4 -> 1360.2
A6: 30 | B6: =((B$13-B$3)/10)+B5 -> 5913.3 | C6: =((C$13-C$3)/10)+C5 -> 5419 | D6: =((D$13-D$3)/10)+D5 -> 4925.1 | E6: =((E$13-E$3)/10)+E5 -> 4431.5 | F6: =((F$13-F$3)/10)+F5 -> 3943.5 | G6: =((G$13-G$3)/10)+G5 -> 3466.7 | H6: =((H$13-H$3)/10)+H5 -> 3014.3 | I6: =((I$13-I$3)/10)+I5 -> 2594.5 | ... L6: =((L$13-L$3)/10)+L5 -> 1563.3
A7: 40 | B7: =((B$13-B$3)/10)+B6 -> 6180.4 | C7: =((C$13-C$3)/10)+C6 -> 5686 | D7: =((D$13-D$3)/10)+D6 -> 5191.8 | E7: =((E$13-E$3)/10)+E6 -> 4698 | F7: =((F$13-F$3)/10)+F6 -> 4209 | G7: =((G$13-G$3)/10)+G6 -> 3729.6 | H7: =((H$13-H$3)/10)+H6 -> 3271.4 | I7: =((I$13-I$3)/10)+I6 -> 2842 | ... L7: =((L$13-L$3)/10)+L6 -> 1766.4
A8: 50 | B8: =((B$13-B$3)/10)+B7 -> 6447.5 | C8: =((C$13-C$3)/10)+C7 -> 5953 | D8: =((D$13-D$3)/10)+D7 -> 5458.5 | E8: =((E$13-E$3)/10)+E7 -> 4964.5 | F8: =((F$13-F$3)/10)+F7 -> 4474.5 | G8: =((G$13-G$3)/10)+G7 -> 3992.5 | H8: =((H$13-H$3)/10)+H7 -> 3528.5 | I8: =((I$13-I$3)/10)+I7 -> 3089.5 | ... L8: =((L$13-L$3)/10)+L7 -> 1969.5
A9: 60 | B9: =((B$13-B$3)/10)+B8 -> 6714.6 | C9: =((C$13-C$3)/10)+C8 -> 6220 | D9: =((D$13-D$3)/10)+D8 -> 5725.2 | E9: =((E$13-E$3)/10)+E8 -> 5231 | F9: =((F$13-F$3)/10)+F8 -> 4740 | G9: =((G$13-G$3)/10)+G8 -> 4255.4 | H9: =((H$13-H$3)/10)+H8 -> 3785.6 | I9: =((I$13-I$3)/10)+I8 -> 3337 | ... L9: =((L$13-L$3)/10)+L8 -> 2172.6
A10: 70 | B10: =((B$13-B$3)/10)+B9 -> 6981.7 | C10: =((C$13-C$3)/10)+C9 -> 6487 | D10: =((D$13-D$3)/10)+D9 -> 5991.9 | E10: =((E$13-E$3)/10)+E9 -> 5497.5 | F10: =((F$13-F$3)/10)+F9 -> 5005.5 | G10: =((G$13-G$3)/10)+G9 -> 4518.3 | H10: =((H$13-H$3)/10)+H9 -> 4042.7 | I10: =((I$13-I$3)/10)+I9 -> 3584.5 | ... L10: =((L$13-L$3)/10)+L9 -> 2375.7
A11: 80 | B11: =((B$13-B$3)/10)+B10 -> 7248.8 | C11: =((C$13-C$3)/10)+C10 -> 6754 | D11: =((D$13-D$3)/10)+D10 -> 6258.6 | E11: =((E$13-E$3)/10)+E10 -> 5764 | F11: =((F$13-F$3)/10)+F10 -> 5271 | G11: =((G$13-G$3)/10)+G10 -> 4781.2 | H11: =((H$13-H$3)/10)+H10 -> 4299.8 | I11: =((I$13-I$3)/10)+I10 -> 3832 | ... L11: =((L$13-L$3)/10)+L10 -> 2578.8
A12: 90 | B12: =((B$13-B$3)/10)+B11 -> 7515.9 | C12: =((C$13-C$3)/10)+C11 -> 7021 | D12: =((D$13-D$3)/10)+D11 -> 6525.3 | E12: =((E$13-E$3)/10)+E11 -> 6030.5 | F12: =((F$13-F$3)/10)+F11 -> 5536.5 | G12: =((G$13-G$3)/10)+G11 -> 5044.1 | H12: =((H$13-H$3)/10)+H11 -> 4556.9 | I12: =((I$13-I$3)/10)+I11 -> 4079.5 | ... L12: =((L$13-L$3)/10)+L11 -> 2781.9
A13: 100 | B13: 7783 | C13: 7288 | D13: 6792 | E13: 6297 | F13: 5802 | G13: 5307 | H13: 4814 | I13: 4327 | J13: 3854 | K13: 3404 | L13: 2985
A14: 110 | B14: =((B$23-B$13)/10)+B13 -> 8056.3 | C14: =((C$23-C$13)/10)+C13 -> 7561.3 | D14: =((D$23-D$13)/10)+D13 -> 7065.4 | E14: =((E$23-E$13)/10)+E13 -> 6570.4 | F14: =((F$23-F$13)/10)+F13 -> 6075.4 | G14: =((G$23-G$13)/10)+G13 -> 5580.4 | H14: =((H$23-H$13)/10)+H13 -> 5087.2 | I14: =((I$23-I$13)/10)+I13 -> 4599.4 | ... L14: =((L$23-L$13)/10)+L13 -> 3244.4
A15: 120 | B15: =((B$23-B$13)/10)+B14 -> 8329.6 | C15: =((C$23-C$13)/10)+C14 -> 7834.6 | D15: =((D$23-D$13)/10)+D14 -> 7338.8 | E15: =((E$23-E$13)/10)+E14 -> 6843.8 | F15: =((F$23-F$13)/10)+F14 -> 6348.8 | G15: =((G$23-G$13)/10)+G14 -> 5853.8 | H15: =((H$23-H$13)/10)+H14 -> 5360.4 | I15: =((I$23-I$13)/10)+I14 -> 4871.8 | ... L15: =((L$23-L$13)/10)+L14 -> 3503.8
A16: 130 | B16: =((B$23-B$13)/10)+B15 -> 8602.9 | C16: =((C$23-C$13)/10)+C15 -> 8107.9 | D16: =((D$23-D$13)/10)+D15 -> 7612.2 | E16: =((E$23-E$13)/10)+E15 -> 7117.2 | F16: =((F$23-F$13)/10)+F15 -> 6622.2 | G16: =((G$23-G$13)/10)+G15 -> 6127.2 | H16: =((H$23-H$13)/10)+H15 -> 5633.6 | I16: =((I$23-I$13)/10)+I15 -> 5144.2 | ... L16: =((L$23-L$13)/10)+L15 -> 3763.2
A17: 140 | B17: =((B$23-B$13)/10)+B16 -> 8876.2 | C17: =((C$23-C$13)/10)+C16 -> 8381.2 | D17: =((D$23-D$13)/10)+D16 -> 7885.6 | E17: =((E$23-E$13)/10)+E16 -> 7390.6 | F17: =((F$23-F$13)/10)+F16 -> 6895.6 | G17: =((G$23-G$13)/10)+G16 -> 6400.6 | H17: =((H$23-H$13)/10)+H16 -> 5906.8 | I17: =((I$23-I$13)/10)+I16 -> 5416.6 | ... L17: =((L$23-L$13)/10)+L16 -> 4022.6
A18: 150 | B18: =((B$23-B$13)/10)+B17 -> 9149.5 | C18: =((C$23-C$13)/10)+C17 -> 8654.5 | D18: =((D$23-D$13)/10)+D17 -> 8159 | E18: =((E$23-E$13)/10)+E17 -> 7664 | F18: =((F$23-F$13)/10)+F17 -> 7169 | G18: =((G$23-G$13)/10)+G17 -> 6674 | H18: =((H$23-H$13)/10)+H17 -> 6180 | I18: =((I$23-I$13)/10)+I17 -> 5689 | ... L18: =((L$23-L$13)/10)+L17 -> 4282
A19: 160 | B19: =((B$23-B$13)/10)+B18 -> 9422.8 | C19: =((C$23-C$13)/10)+C18 -> 8927.8 | D19: =((D$23-D$13)/10)+D18 -> 8432.4 | E19: =((E$23-E$13)/10)+E18 -> 7937.4 | F19: =((F$23-F$13)/10)+F18 -> 7442.4 | G19: =((G$23-G$13)/10)+G18 -> 6947.4 | H19: =((H$23-H$13)/10)+H18 -> 6453.2 | I19: =((I$23-I$13)/10)+I18 -> 5961.4 | ... L19: =((L$23-L$13)/10)+L18 -> 4541.4
A20: 170 | B20: =((B$23-B$13)/10)+B19 -> 9696.1 | C20: =((C$23-C$13)/10)+C19 -> 9201.1 | D20: =((D$23-D$13)/10)+D19 -> 8705.8 | E20: =((E$23-E$13)/10)+E19 -> 8210.8 | F20: =((F$23-F$13)/10)+F19 -> 7715.8 | G20: =((G$23-G$13)/10)+G19 -> 7220.8 | H20: =((H$23-H$13)/10)+H19 -> 6726.4 | I20: =((I$23-I$13)/10)+I19 -> 6233.8 | ... L20: =((L$23-L$13)/10)+L19 -> 4800.8
A21: 180 | B21: =((B$23-B$13)/10)+B20 -> 9969.4 | C21: =((C$23-C$13)/10)+C20 -> 9474.4 | D21: =((D$23-D$13)/10)+D20 -> 8979.2 | E21: =((E$23-E$13)/10)+E20 -> 8484.2 | F21: =((F$23-F$13)/10)+F20 -> 7989.2 | G21: =((G$23-G$13)/10)+G20 -> 7494.2 | H21: =((H$23-H$13)/10)+H20 -> 6999.6 | I21: =((I$23-I$13)/10)+I20 -> 6506.2 | ... L21: =((L$23-L$13)/10)+L20 -> 5060.2
A22: 190 | B22: =((B$23-B$13)/10)+B21 -> 10242.7 | C22: =((C$23-C$13)/10)+C21 -> 9747.7 | D22: =((D$23-D$13)/10)+D21 -> 9252.6 | E22: =((E$23-E$13)/10)+E21 -> 8757.6 | F22: =((F$23-F$13)/10)+F21 -> 8262.6 | G22: =((G$23-G$13)/10)+G21 -> 7767.6 | H22: =((H$23-H$13)/10)+H21 -> 7272.8 | I22: =((I$23-I$13)/10)+I21 -> 6778.6 | ... L22: =((L$23-L$13)/10)+L21 -> 5319.6
A23: 200 | B23: 10516 | C23: 10021 | D23: 9526 | E23: 9031 | F23: 8536 | G23: 8041 | H23: 7546 | I23: 7051 | J23: 6556 | K23: 6064 | L23: 5579
A24: 210 | B24: =((B$33-B$23)/10)+B23 -> 10790 | C24: =((C$33-C$23)/10)+C23 -> 10295 | D24: =((D$33-D$23)/10)+D23 -> 9800 | E24: =((E$33-E$23)/10)+E23 -> 9305 | F24: =((F$33-F$23)/10)+F23 -> 8810 | G24: =((G$33-G$23)/10)+G23 -> 8315 | H24: =((H$33-H$23)/10)+H23 -> 7820 | I24: =((I$33-I$23)/10)+I23 -> 7325 | ... L24: =((L$33-L$23)/10)+L23 -> 5851.7
A25: 220 | B25: =((B$33-B$23)/10)+B24 -> 11064 | C25: =((C$33-C$23)/10)+C24 -> 10569 | D25: =((D$33-D$23)/10)+D24 -> 10074 | E25: =((E$33-E$23)/10)+E24 -> 9579 | F25: =((F$33-F$23)/10)+F24 -> 9084 | G25: =((G$33-G$23)/10)+G24 -> 8589 | H25: =((H$33-H$23)/10)+H24 -> 8094 | I25: =((I$33-I$23)/10)+I24 -> 7599 | ... L25: =((L$33-L$23)/10)+L24 -> 6124.4
A26: 230 | B26: =((B$33-B$23)/10)+B25 -> 11338 | C26: =((C$33-C$23)/10)+C25 -> 10843 | D26: =((D$33-D$23)/10)+D25 -> 10348 | E26: =((E$33-E$23)/10)+E25 -> 9853 | F26: =((F$33-F$23)/10)+F25 -> 9358 | G26: =((G$33-G$23)/10)+G25 -> 8863 | H26: =((H$33-H$23)/10)+H25 -> 8368 | I26: =((I$33-I$23)/10)+I25 -> 7873 | ... L26: =((L$33-L$23)/10)+L25 -> 6397.1
A27: 240 | B27: =((B$33-B$23)/10)+B26 -> 11612 | C27: =((C$33-C$23)/10)+C26 -> 11117 | D27: =((D$33-D$23)/10)+D26 -> 10622 | E27: =((E$33-E$23)/10)+E26 -> 10127 | F27: =((F$33-F$23)/10)+F26 -> 9632 | G27: =((G$33-G$23)/10)+G26 -> 9137 | H27: =((H$33-H$23)/10)+H26 -> 8642 | I27: =((I$33-I$23)/10)+I26 -> 8147 | ... L27: =((L$33-L$23)/10)+L26 -> 6669.8
A28: 250 | B28: =((B$33-B$23)/10)+B27 -> 11886 | C28: =((C$33-C$23)/10)+C27 -> 11391 | D28: =((D$33-D$23)/10)+D27 -> 10896 | E28: =((E$33-E$23)/10)+E27 -> 10401 | F28: =((F$33-F$23)/10)+F27 -> 9906 | G28: =((G$33-G$23)/10)+G27 -> 9411 | H28: =((H$33-H$23)/10)+H27 -> 8916 | I28: =((I$33-I$23)/10)+I27 -> 8421 | ... L28: =((L$33-L$23)/10)+L27 -> 6942.5
A29: 260 | B29: =((B$33-B$23)/10)+B28 -> 12160 | C29: =((C$33-C$23)/10)+C28 -> 11665 | D29: =((D$33-D$23)/10)+D28 -> 11170 | E29: =((E$33-E$23)/10)+E28 -> 10675 | F29: =((F$33-F$23)/10)+F28 -> 10180 | G29: =((G$33-G$23)/10)+G28 -> 9685 | H29: =((H$33-H$23)/10)+H28 -> 9190 | I29: =((I$33-I$23)/10)+I28 -> 8695 | ... L29: =((L$33-L$23)/10)+L28 -> 7215.2
A30: 270 | B30: =((B$33-B$23)/10)+B29 -> 12434 | C30: =((C$33-C$23)/10)+C29 -> 11939 | D30: =((D$33-D$23)/10)+D29 -> 11444 | E30: =((E$33-E$23)/10)+E29 -> 10949 | F30: =((F$33-F$23)/10)+F29 -> 10454 | G30: =((G$33-G$23)/10)+G29 -> 9959 | H30: =((H$33-H$23)/10)+H29 -> 9464 | I30: =((I$33-I$23)/10)+I29 -> 8969 | ... L30: =((L$33-L$23)/10)+L29 -> 7487.9
A31: 280 | B31: =((B$33-B$23)/10)+B30 -> 12708 | C31: =((C$33-C$23)/10)+C30 -> 12213 | D31: =((D$33-D$23)/10)+D30 -> 11718 | E31: =((E$33-E$23)/10)+E30 -> 11223 | F31: =((F$33-F$23)/10)+F30 -> 10728 | G31: =((G$33-G$23)/10)+G30 -> 10233 | H31: =((H$33-H$23)/10)+H30 -> 9738 | I31: =((I$33-I$23)/10)+I30 -> 9243 | ... L31: =((L$33-L$23)/10)+L30 -> 7760.6
A32: 290 | B32: =((B$33-B$23)/10)+B31 -> 12982 | C32: =((C$33-C$23)/10)+C31 -> 12487 | D32: =((D$33-D$23)/10)+D31 -> 11992 | E32: =((E$33-E$23)/10)+E31 -> 11497 | F32: =((F$33-F$23)/10)+F31 -> 11002 | G32: =((G$33-G$23)/10)+G31 -> 10507 | H32: =((H$33-H$23)/10)+H31 -> 10012 | I32: =((I$33-I$23)/10)+I31 -> 9517 | ... L32: =((L$33-L$23)/10)+L31 -> 8033.3
A33: 300 | B33: 13256 | C33: 12761 | D33: 12266 | E33: 11771 | F33: 11276 | G33: 10781 | H33: 10286 | I33: 9791 | J33: 9296 | K33: 8801 | L33: 8306
A34: 310 | B34: =((B$43-B$33)/10)+B33 -> 13430 | C34: =((C$43-C$33)/10)+C33 -> 13035 | D34: =((D$43-D$33)/10)+D33 -> 12540 | E34: =((E$43-E$33)/10)+E33 -> 12045 | F34: =((F$43-F$33)/10)+F33 -> 11550 | G34: =((G$43-G$33)/10)+G33 -> 11055 | H34: =((H$43-H$33)/10)+H33 -> 10560 | I34: =((I$43-I$33)/10)+I33 -> 10065 | ... L34: =((L$43-L$33)/10)+L33 -> 8580
A35: 320 | B35: =((B$43-B$33)/10)+B34 -> 13604 | C35: =((C$43-C$33)/10)+C34 -> 13309 | D35: =((D$43-D$33)/10)+D34 -> 12814 | E35: =((E$43-E$33)/10)+E34 -> 12319 | F35: =((F$43-F$33)/10)+F34 -> 11824 | G35: =((G$43-G$33)/10)+G34 -> 11329 | H35: =((H$43-H$33)/10)+H34 -> 10834 | I35: =((I$43-I$33)/10)+I34 -> 10339 | ... L35: =((L$43-L$33)/10)+L34 -> 8854
A36: 330 | B36: =((B$43-B$33)/10)+B35 -> 13778 | C36: =((C$43-C$33)/10)+C35 -> 13583 | D36: =((D$43-D$33)/10)+D35 -> 13088 | E36: =((E$43-E$33)/10)+E35 -> 12593 | F36: =((F$43-F$33)/10)+F35 -> 12098 | G36: =((G$43-G$33)/10)+G35 -> 11603 | H36: =((H$43-H$33)/10)+H35 -> 11108 | I36: =((I$43-I$33)/10)+I35 -> 10613 | ... L36: =((L$43-L$33)/10)+L35 -> 9128
A37: 340 | B37: =((B$43-B$33)/10)+B36 -> 13952 | C37: =((C$43-C$33)/10)+C36 -> 13857 | D37: =((D$43-D$33)/10)+D36 -> 13362 | E37: =((E$43-E$33)/10)+E36 -> 12867 | F37: =((F$43-F$33)/10)+F36 -> 12372 | G37: =((G$43-G$33)/10)+G36 -> 11877 | H37: =((H$43-H$33)/10)+H36 -> 11382 | I37: =((I$43-I$33)/10)+I36 -> 10887 | ... L37: =((L$43-L$33)/10)+L36 -> 9402
A38: 350 | B38: =((B$43-B$33)/10)+B37 -> 14126 | C38: =((C$43-C$33)/10)+C37 -> 14131 | D38: =((D$43-D$33)/10)+D37 -> 13636 | E38: =((E$43-E$33)/10)+E37 -> 13141 | F38: =((F$43-F$33)/10)+F37 -> 12646 | G38: =((G$43-G$33)/10)+G37 -> 12151 | H38: =((H$43-H$33)/10)+H37 -> 11656 | I38: =((I$43-I$33)/10)+I37 -> 11161 | ... L38: =((L$43-L$33)/10)+L37 -> 9676
A39: 360 | B39: =((B$43-B$33)/10)+B38 -> 14300 | C39: =((C$43-C$33)/10)+C38 -> 14405 | D39: =((D$43-D$33)/10)+D38 -> 13910 | E39: =((E$43-E$33)/10)+E38 -> 13415 | F39: =((F$43-F$33)/10)+F38 -> 12920 | G39: =((G$43-G$33)/10)+G38 -> 12425 | H39: =((H$43-H$33)/10)+H38 -> 11930 | I39: =((I$43-I$33)/10)+I38 -> 11435 | ... L39: =((L$43-L$33)/10)+L38 -> 9950
A40: 370 | B40: =((B$43-B$33)/10)+B39 -> 14474 | C40: =((C$43-C$33)/10)+C39 -> 14679 | D40: =((D$43-D$33)/10)+D39 -> 14184 | E40: =((E$43-E$33)/10)+E39 -> 13689 | F40: =((F$43-F$33)/10)+F39 -> 13194 | G40: =((G$43-G$33)/10)+G39 -> 12699 | H40: =((H$43-H$33)/10)+H39 -> 12204 | I40: =((I$43-I$33)/10)+I39 -> 11709 | ... L40: =((L$43-L$33)/10)+L39 -> 10224
...

Sheet ARM
A1: ALTURA | B1: TRIM TQ ARMAZ
B2: -50 | C2: -40 | D2: -30 | E2: -20 | F2: -10 | G2: 0 | H2: 10 | I2: 20 | J2: 30 | K2: 40 | L2: 50
A3: 0 | B3: 14 | C3: 14 | D3: 14 | E3: 14 | F3: 14 | G3: 14 | H3: 14 | I3: 14 | J3: 14 | K3: 14 | L3: 14
A4: 10 | B4: =((B$13-B$3)/10)+B3 -> 21.2 | C4: =((C$13-C$3)/10)+C3 -> 21.3 | D4: =((D$13-D$3)/10)+D3 -> 21.4 | E4: =((E$13-E$3)/10)+E3 -> 21.5 | F4: =((F$13-F$3)/10)+F3 -> 21.6 | G4: =((G$13-G$3)/10)+G3 -> 21.7 | H4: =((H$13-H$3)/10)+H3 -> 21.8 | I4: =((I$13-I$3)/10)+I3 -> 21.9 | ... L4: =((L$13-L$3)/10)+L3 -> 22.5
A5: 20 | B5: =((B$13-B$3)/10)+B4 -> 28.4 | C5: =((C$13-C$3)/10)+C4 -> 28.6 | D5: =((D$13-D$3)/10)+D4 -> 28.8 | E5: =((E$13-E$3)/10)+E4 -> 29 | F5: =((F$13-F$3)/10)+F4 -> 29.2 | G5: =((G$13-G$3)/10)+G4 -> 29.4 | H5: =((H$13-H$3)/10)+H4 -> 29.6 | I5: =((I$13-I$3)/10)+I4 -> 29.8 | ... L5: =((L$13-L$3)/10)+L4 -> 31
A6: 30 | B6: =((B$13-B$3)/10)+B5 -> 35.6 | C6: =((C$13-C$3)/10)+C5 -> 35.9 | D6: =((D$13-D$3)/10)+D5 -> 36.2 | E6: =((E$13-E$3)/10)+E5 -> 36.5 | F6: =((F$13-F$3)/10)+F5 -> 36.8 | G6: =((G$13-G$3)/10)+G5 -> 37.1 | H6: =((H$13-H$3)/10)+H5 -> 37.4 | I6: =((I$13-I$3)/10)+I5 -> 37.7 | ... L6: =((L$13-L$3)/10)+L5 -> 39.5
A7: 40 | B7: =((B$13-B$3)/10)+B6 -> 42.8 | C7: =((C$13-C$3)/10)+C6 -> 43.2 | D7: =((D$13-D$3)/10)+D6 -> 43.6 | E7: =((E$13-E$3)/10)+E6 -> 44 | F7: =((F$13-F$3)/10)+F6 -> 44.4 | G7: =((G$13-G$3)/10)+G6 -> 44.8 | H7: =((H$13-H$3)/10)+H6 -> 45.2 | I7: =((I$13-I$3)/10)+I6 -> 45.6 | ... L7: =((L$13-L$3)/10)+L6 -> 48
A8: 50 | B8: =((B$13-B$3)/10)+B7 -> 50 | C8: =((C$13-C$3)/10)+C7 -> 50.5 | D8: =((D$13-D$3)/10)+D7 -> 51 | E8: =((E$13-E$3)/10)+E7 -> 51.5 | F8: =((F$13-F$3)/10)+F7 -> 52 | G8: =((G$13-G$3)/10)+G7 -> 52.5 | H8: =((H$13-H$3)/10)+H7 -> 53 | I8: =((I$13-I$3)/10)+I7 -> 53.5 | ... L8: =((L$13-L$3)/10)+L7 -> 56.5
A9: 60 | B9: =((B$13-B$3)/10)+B8 -> 57.2 | C9: =((C$13-C$3)/10)+C8 -> 57.8 | D9: =((D$13-D$3)/10)+D8 -> 58.4 | E9: =((E$13-E$3)/10)+E8 -> 59 | F9: =((F$13-F$3)/10)+F8 -> 59.6 | G9: =((G$13-G$3)/10)+G8 -> 60.2 | H9: =((H$13-H$3)/10)+H8 -> 60.8 | I9: =((I$13-I$3)/10)+I8 -> 61.4 | ... L9: =((L$13-L$3)/10)+L8 -> 65
A10: 70 | B10: =((B$13-B$3)/10)+B9 -> 64.4 | C10: =((C$13-C$3)/10)+C9 -> 65.1 | D10: =((D$13-D$3)/10)+D9 -> 65.8 | E10: =((E$13-E$3)/10)+E9 -> 66.5 | F10: =((F$13-F$3)/10)+F9 -> 67.2 | G10: =((G$13-G$3)/10)+G9 -> 67.9 | H10: =((H$13-H$3)/10)+H9 -> 68.6 | I10: =((I$13-I$3)/10)+I9 -> 69.3 | ... L10: =((L$13-L$3)/10)+L9 -> 73.5
A11: 80 | B11: =((B$13-B$3)/10)+B10 -> 71.6 | C11: =((C$13-C$3)/10)+C10 -> 72.4 | D11: =((D$13-D$3)/10)+D10 -> 73.2 | E11: =((E$13-E$3)/10)+E10 -> 74 | F11: =((F$13-F$3)/10)+F10 -> 74.8 | G11: =((G$13-G$3)/10)+G10 -> 75.6 | H11: =((H$13-H$3)/10)+H10 -> 76.4 | I11: =((I$13-I$3)/10)+I10 -> 77.2 | ... L11: =((L$13-L$3)/10)+L10 -> 82
A12: 90 | B12: =((B$13-B$3)/10)+B11 -> 78.8 | C12: =((C$13-C$3)/10)+C11 -> 79.7 | D12: =((D$13-D$3)/10)+D11 -> 80.6 | E12: =((E$13-E$3)/10)+E11 -> 81.5 | F12: =((F$13-F$3)/10)+F11 -> 82.4 | G12: =((G$13-G$3)/10)+G11 -> 83.3 | H12: =((H$13-H$3)/10)+H11 -> 84.2 | I12: =((I$13-I$3)/10)+I11 -> 85.1 | ... L12: =((L$13-L$3)/10)+L11 -> 90.5
A13: 100 | B13: 86 | C13: 87 | D13: 88 | E13: 89 | F13: 90 | G13: 91 | H13: 92 | I13: 93 | J13: 96 | K13: 97 | L13: 99
A14: 110 | B14: =((B$23-B$13)/10)+B13 -> 102.8 | C14: =((C$23-C$13)/10)+C13 -> 104 | D14: =((D$23-D$13)/10)+D13 -> 105.3 | E14: =((E$23-E$13)/10)+E13 -> 106.6 | F14: =((F$23-F$13)/10)+F13 -> 107.9 | G14: =((G$23-G$13)/10)+G13 -> 109.2 | H14: =((H$23-H$13)/10)+H13 -> 110.6 | I14: =((I$23-I$13)/10)+I13 -> 112 | ... L14: =((L$23-L$13)/10)+L13 -> 119.1
A15: 120 | B15: =((B$23-B$13)/10)+B14 -> 119.6 | C15: =((C$23-C$13)/10)+C14 -> 121 | D15: =((D$23-D$13)/10)+D14 -> 122.6 | E15: =((E$23-E$13)/10)+E14 -> 124.2 | F15: =((F$23-F$13)/10)+F14 -> 125.8 | G15: =((G$23-G$13)/10)+G14 -> 127.4 | H15: =((H$23-H$13)/10)+H14 -> 129.2 | I15: =((I$23-I$13)/10)+I14 -> 131 | ... L15: =((L$23-L$13)/10)+L14 -> 139.2
A16: 130 | B16: =((B$23-B$13)/10)+B15 -> 136.4 | C16: =((C$23-C$13)/10)+C15 -> 138 | D16: =((D$23-D$13)/10)+D15 -> 139.9 | E16: =((E$23-E$13)/10)+E15 -> 141.8 | F16: =((F$23-F$13)/10)+F15 -> 143.7 | G16: =((G$23-G$13)/10)+G15 -> 145.6 | H16: =((H$23-H$13)/10)+H15 -> 147.8 | I16: =((I$23-I$13)/10)+I15 -> 150 | ... L16: =((L$23-L$13)/10)+L15 -> 159.3
A17: 140 | B17: =((B$23-B$13)/10)+B16 -> 153.2 | C17: =((C$23-C$13)/10)+C16 -> 155 | D17: =((D$23-D$13)/10)+D16 -> 157.2 | E17: =((E$23-E$13)/10)+E16 -> 159.4 | F17: =((F$23-F$13)/10)+F16 -> 161.6 | G17: =((G$23-G$13)/10)+G16 -> 163.8 | H17: =((H$23-H$13)/10)+H16 -> 166.4 | I17: =((I$23-I$13)/10)+I16 -> 169 | ... L17: =((L$23-L$13)/10)+L16 -> 179.4
A18: 150 | B18: =((B$23-B$13)/10)+B17 -> 170 | C18: =((C$23-C$13)/10)+C17 -> 172 | D18: =((D$23-D$13)/10)+D17 -> 174.5 | E18: =((E$23-E$13)/10)+E17 -> 177 | F18: =((F$23-F$13)/10)+F17 -> 179.5 | G18: =((G$23-G$13)/10)+G17 -> 182 | H18: =((H$23-H$13)/10)+H17 -> 185 | I18: =((I$23-I$13)/10)+I17 -> 188 | ... L18: =((L$23-L$13)/10)+L17 -> 199.5
A19: 160 | B19: =((B$23-B$13)/10)+B18 -> 186.8 | C19: =((C$23-C$13)/10)+C18 -> 189 | D19: =((D$23-D$13)/10)+D18 -> 191.8 | E19: =((E$23-E$13)/10)+E18 -> 194.6 | F19: =((F$23-F$13)/10)+F18 -> 197.4 | G19: =((G$23-G$13)/10)+G18 -> 200.2 | H19: =((H$23-H$13)/10)+H18 -> 203.6 | I19: =((I$23-I$13)/10)+I18 -> 207 | ... L19: =((L$23-L$13)/10)+L18 -> 219.6
A20: 170 | B20: =((B$23-B$13)/10)+B19 -> 203.6 | C20: =((C$23-C$13)/10)+C19 -> 206 | D20: =((D$23-D$13)/10)+D19 -> 209.1 | E20: =((E$23-E$13)/10)+E19 -> 212.2 | F20: =((F$23-F$13)/10)+F19 -> 215.3 | G20: =((G$23-G$13)/10)+G19 -> 218.4 | H20: =((H$23-H$13)/10)+H19 -> 222.2 | I20: =((I$23-I$13)/10)+I19 -> 226 | ... L20: =((L$23-L$13)/10)+L19 -> 239.7
A21: 180 | B21: =((B$23-B$13)/10)+B20 -> 220.4 | C21: =((C$23-C$13)/10)+C20 -> 223 | D21: =((D$23-D$13)/10)+D20 -> 226.4 | E21: =((E$23-E$13)/10)+E20 -> 229.8 | F21: =((F$23-F$13)/10)+F20 -> 233.2 | G21: =((G$23-G$13)/10)+G20 -> 236.6 | H21: =((H$23-H$13)/10)+H20 -> 240.8 | I21: =((I$23-I$13)/10)+I20 -> 245 | ... L21: =((L$23-L$13)/10)+L20 -> 259.8
A22: 190 | B22: =((B$23-B$13)/10)+B21 -> 237.2 | C22: =((C$23-C$13)/10)+C21 -> 240 | D22: =((D$23-D$13)/10)+D21 -> 243.7 | E22: =((E$23-E$13)/10)+E21 -> 247.4 | F22: =((F$23-F$13)/10)+F21 -> 251.1 | G22: =((G$23-G$13)/10)+G21 -> 254.8 | H22: =((H$23-H$13)/10)+H21 -> 259.4 | I22: =((I$23-I$13)/10)+I21 -> 264 | ... L22: =((L$23-L$13)/10)+L21 -> 279.9
A23: 200 | B23: 254 | C23: 257 | D23: 261 | E23: 265 | F23: 269 | G23: 273 | H23: 278 | I23: 283 | J23: 288 | K23: 294 | L23: 300
A24: 210 | B24: =((B$33-B$23)/10)+B23 -> 283.9 | C24: =((C$33-C$23)/10)+C23 -> 287.5 | D24: =((D$33-D$23)/10)+D23 -> 292 | E24: =((E$33-E$23)/10)+E23 -> 296.4 | F24: =((F$33-F$23)/10)+F23 -> 301 | G24: =((G$33-G$23)/10)+G23 -> 305.5 | H24: =((H$33-H$23)/10)+H23 -> 311 | I24: =((I$33-I$23)/10)+I23 -> 316.5 | ... L24: =((L$33-L$23)/10)+L23 -> 335.1
A25: 220 | B25: =((B$33-B$23)/10)+B24 -> 313.8 | C25: =((C$33-C$23)/10)+C24 -> 318 | D25: =((D$33-D$23)/10)+D24 -> 323 | E25: =((E$33-E$23)/10)+E24 -> 327.8 | F25: =((F$33-F$23)/10)+F24 -> 333 | G25: =((G$33-G$23)/10)+G24 -> 338 | H25: =((H$33-H$23)/10)+H24 -> 344 | I25: =((I$33-I$23)/10)+I24 -> 350 | ... L25: =((L$33-L$23)/10)+L24 -> 370.2
A26: 230 | B26: =((B$33-B$23)/10)+B25 -> 343.7 | C26: =((C$33-C$23)/10)+C25 -> 348.5 | D26: =((D$33-D$23)/10)+D25 -> 354 | E26: =((E$33-E$23)/10)+E25 -> 359.2 | F26: =((F$33-F$23)/10)+F25 -> 365 | G26: =((G$33-G$23)/10)+G25 -> 370.5 | H26: =((H$33-H$23)/10)+H25 -> 377 | I26: =((I$33-I$23)/10)+I25 -> 383.5 | ... L26: =((L$33-L$23)/10)+L25 -> 405.3
A27: 240 | B27: =((B$33-B$23)/10)+B26 -> 373.6 | C27: =((C$33-C$23)/10)+C26 -> 379 | D27: =((D$33-D$23)/10)+D26 -> 385 | E27: =((E$33-E$23)/10)+E26 -> 390.6 | F27: =((F$33-F$23)/10)+F26 -> 397 | G27: =((G$33-G$23)/10)+G26 -> 403 | H27: =((H$33-H$23)/10)+H26 -> 410 | I27: =((I$33-I$23)/10)+I26 -> 417 | ... L27: =((L$33-L$23)/10)+L26 -> 440.4
A28: 250 | B28: =((B$33-B$23)/10)+B27 -> 403.5 | C28: =((C$33-C$23)/10)+C27 -> 409.5 | D28: =((D$33-D$23)/10)+D27 -> 416 | E28: =((E$33-E$23)/10)+E27 -> 422 | F28: =((F$33-F$23)/10)+F27 -> 429 | G28: =((G$33-G$23)/10)+G27 -> 435.5 | H28: =((H$33-H$23)/10)+H27 -> 443 | I28: =((I$33-I$23)/10)+I27 -> 450.5 | ... L28: =((L$33-L$23)/10)+L27 -> 475.5
A29: 260 | B29: =((B$33-B$23)/10)+B28 -> 433.4 | C29: =((C$33-C$23)/10)+C28 -> 440 | D29: =((D$33-D$23)/10)+D28 -> 447 | E29: =((E$33-E$23)/10)+E28 -> 453.4 | F29: =((F$33-F$23)/10)+F28 -> 461 | G29: =((G$33-G$23)/10)+G28 -> 468 | H29: =((H$33-H$23)/10)+H28 -> 476 | I29: =((I$33-I$23)/10)+I28 -> 484 | ... L29: =((L$33-L$23)/10)+L28 -> 510.6
A30: 270 | B30: =((B$33-B$23)/10)+B29 -> 463.3 | C30: =((C$33-C$23)/10)+C29 -> 470.5 | D30: =((D$33-D$23)/10)+D29 -> 478 | E30: =((E$33-E$23)/10)+E29 -> 484.8 | F30: =((F$33-F$23)/10)+F29 -> 493 | G30: =((G$33-G$23)/10)+G29 -> 500.5 | H30: =((H$33-H$23)/10)+H29 -> 509 | I30: =((I$33-I$23)/10)+I29 -> 517.5 | ... L30: =((L$33-L$23)/10)+L29 -> 545.7
A31: 280 | B31: =((B$33-B$23)/10)+B30 -> 493.2 | C31: =((C$33-C$23)/10)+C30 -> 501 | D31: =((D$33-D$23)/10)+D30 -> 509 | E31: =((E$33-E$23)/10)+E30 -> 516.2 | F31: =((F$33-F$23)/10)+F30 -> 525 | G31: =((G$33-G$23)/10)+G30 -> 533 | H31: =((H$33-H$23)/10)+H30 -> 542 | I31: =((I$33-I$23)/10)+I30 -> 551 | ... L31: =((L$33-L$23)/10)+L30 -> 580.8
A32: 290 | B32: =((B$33-B$23)/10)+B31 -> 523.1 | C32: =((C$33-C$23)/10)+C31 -> 531.5 | D32: =((D$33-D$23)/10)+D31 -> 540 | E32: =((E$33-E$23)/10)+E31 -> 547.6 | F32: =((F$33-F$23)/10)+F31 -> 557 | G32: =((G$33-G$23)/10)+G31 -> 565.5 | H32: =((H$33-H$23)/10)+H31 -> 575 | I32: =((I$33-I$23)/10)+I31 -> 584.5 | ... L32: =((L$33-L$23)/10)+L31 -> 615.9
A33: 300 | B33: 553 | C33: 562 | D33: 571 | E33: 579 | F33: 589 | G33: 598 | H33: 608 | I33: 618 | J33: 629 | K33: 640 | L33: 651
A34: 310 | B34: =((B$43-B$33)/10)+B33 -> 597.5 | C34: =((C$43-C$33)/10)+C33 -> 607 | D34: =((D$43-D$33)/10)+D33 -> 616.5 | E34: =((E$43-E$33)/10)+E33 -> 625.1 | F34: =((F$43-F$33)/10)+F33 -> 635.6 | G34: =((G$43-G$33)/10)+G33 -> 645.3 | H34: =((H$43-H$33)/10)+H33 -> 655.8 | I34: =((I$43-I$33)/10)+I33 -> 666.4 | ... L34: =((L$43-L$33)/10)+L33 -> 701.1
A35: 320 | B35: =((B$43-B$33)/10)+B34 -> 642 | C35: =((C$43-C$33)/10)+C34 -> 652 | D35: =((D$43-D$33)/10)+D34 -> 662 | E35: =((E$43-E$33)/10)+E34 -> 671.2 | F35: =((F$43-F$33)/10)+F34 -> 682.2 | G35: =((G$43-G$33)/10)+G34 -> 692.6 | H35: =((H$43-H$33)/10)+H34 -> 703.6 | I35: =((I$43-I$33)/10)+I34 -> 714.8 | ... L35: =((L$43-L$33)/10)+L34 -> 751.2
A36: 330 | B36: =((B$43-B$33)/10)+B35 -> 686.5 | C36: =((C$43-C$33)/10)+C35 -> 697 | D36: =((D$43-D$33)/10)+D35 -> 707.5 | E36: =((E$43-E$33)/10)+E35 -> 717.3 | F36: =((F$43-F$33)/10)+F35 -> 728.8 | G36: =((G$43-G$33)/10)+G35 -> 739.9 | H36: =((H$43-H$33)/10)+H35 -> 751.4 | I36: =((I$43-I$33)/10)+I35 -> 763.2 | ... L36: =((L$43-L$33)/10)+L35 -> 801.3
A37: 340 | B37: =((B$43-B$33)/10)+B36 -> 731 | C37: =((C$43-C$33)/10)+C36 -> 742 | D37: =((D$43-D$33)/10)+D36 -> 753 | E37: =((E$43-E$33)/10)+E36 -> 763.4 | F37: =((F$43-F$33)/10)+F36 -> 775.4 | G37: =((G$43-G$33)/10)+G36 -> 787.2 | H37: =((H$43-H$33)/10)+H36 -> 799.2 | I37: =((I$43-I$33)/10)+I36 -> 811.6 | ... L37: =((L$43-L$33)/10)+L36 -> 851.4
A38: 350 | B38: =((B$43-B$33)/10)+B37 -> 775.5 | C38: =((C$43-C$33)/10)+C37 -> 787 | D38: =((D$43-D$33)/10)+D37 -> 798.5 | E38: =((E$43-E$33)/10)+E37 -> 809.5 | F38: =((F$43-F$33)/10)+F37 -> 822 | G38: =((G$43-G$33)/10)+G37 -> 834.5 | H38: =((H$43-H$33)/10)+H37 -> 847 | I38: =((I$43-I$33)/10)+I37 -> 860 | ... L38: =((L$43-L$33)/10)+L37 -> 901.5
A39: 360 | B39: =((B$43-B$33)/10)+B38 -> 820 | C39: =((C$43-C$33)/10)+C38 -> 832 | D39: =((D$43-D$33)/10)+D38 -> 844 | E39: =((E$43-E$33)/10)+E38 -> 855.6 | F39: =((F$43-F$33)/10)+F38 -> 868.6 | G39: =((G$43-G$33)/10)+G38 -> 881.8 | H39: =((H$43-H$33)/10)+H38 -> 894.8 | I39: =((I$43-I$33)/10)+I38 -> 908.4 | ... L39: =((L$43-L$33)/10)+L38 -> 951.6
A40: 370 | B40: =((B$43-B$33)/10)+B39 -> 864.5 | C40: =((C$43-C$33)/10)+C39 -> 877 | D40: =((D$43-D$33)/10)+D39 -> 889.5 | E40: =((E$43-E$33)/10)+E39 -> 901.7 | F40: =((F$43-F$33)/10)+F39 -> 915.2 | G40: =((G$43-G$33)/10)+G39 -> 929.1 | H40: =((H$43-H$33)/10)+H39 -> 942.6 | I40: =((I$43-I$33)/10)+I39 -> 956.8 | ... L40: =((L$43-L$33)/10)+L39 -> 1001.7
...

Sheet DIARIO
A1: ALTURA | B1: VOLUME
A2: 0 | B2: 188
A3: 10 | B3: =((B$12-B$2)/10)+B2 -> 225.7
A4: 20 | B4: =((B$12-B$2)/10)+B3 -> 263.4
A5: 30 | B5: =((B$12-B$2)/10)+B4 -> 301.1
A6: 40 | B6: =((B$12-B$2)/10)+B5 -> 338.8
A7: 50 | B7: =((B$12-B$2)/10)+B6 -> 376.5
A8: 60 | B8: =((B$12-B$2)/10)+B7 -> 414.2
A9: 70 | B9: =((B$12-B$2)/10)+B8 -> 451.9
A10: 80 | B10: =((B$12-B$2)/10)+B9 -> 489.6
A11: 90 | B11: =((B$12-B$2)/10)+B10 -> 527.3
A12: 100 | B12: 565
A13: 110 | B13: =((B$22-B$12)/10)+B12 -> 602.8
A14: 120 | B14: =((B$22-B$12)/10)+B13 -> 640.6
A15: 130 | B15: =((B$22-B$12)/10)+B14 -> 678.4
A16: 140 | B16: =((B$22-B$12)/10)+B15 -> 716.2
A17: 150 | B17: =((B$22-B$12)/10)+B16 -> 754
A18: 160 | B18: =((B$22-B$12)/10)+B17 -> 791.8
A19: 170 | B19: =((B$22-B$12)/10)+B18 -> 829.6
A20: 180 | B20: =((B$22-B$12)/10)+B19 -> 867.4
A21: 190 | B21: =((B$22-B$12)/10)+B20 -> 905.2
A22: 200 | B22: 943
A23: 210 | B23: =((B$32-B$22)/10)+B22 -> 980.9
A24: 220 | B24: =((B$32-B$22)/10)+B23 -> 1018.8
A25: 230 | B25: =((B$32-B$22)/10)+B24 -> 1056.7
A26: 240 | B26: =((B$32-B$22)/10)+B25 -> 1094.6
A27: 250 | B27: =((B$32-B$22)/10)+B26 -> 1132.5
A28: 260 | B28: =((B$32-B$22)/10)+B27 -> 1170.4
A29: 270 | B29: =((B$32-B$22)/10)+B28 -> 1208.3
A30: 280 | B30: =((B$32-B$22)/10)+B29 -> 1246.2
A31: 290 | B31: =((B$32-B$22)/10)+B30 -> 1284.1
A32: 300 | B32: 1322
A33: 310 | B33: =((B$42-B$32)/10)+B32 -> 1360
A34: 320 | B34: =((B$42-B$32)/10)+B33 -> 1398
A35: 330 | B35: =((B$42-B$32)/10)+B34 -> 1436
A36: 340 | B36: =((B$42-B$32)/10)+B35 -> 1474
A37: 350 | B37: =((B$42-B$32)/10)+B36 -> 1512
A38: 360 | B38: =((B$42-B$32)/10)+B37 -> 1550
A39: 370 | B39: =((B$42-B$32)/10)+B38 -> 1588
A40: 380 | B40: =((B$42-B$32)/10)+B39 -> 1626
...
