Workbook

Sheet SONDAGEM
A1: SONDAGEM CLASSE A - ASD 2411 | E1: TRIM & VOLUME (LTS) | O1: %
A2: TANQUE | C2: SONDAGEM CM | D2: CAPACIDADE LTS | E2: -1400 | F2: -1200 | G2: -1000 | H2: -800 | I2: -600 | J2: -400 | K2: -200 | L2: 0 | M2: 200 | N2: 400
A3: TK4 | B3: FUEL OIL HEADER | C3: 220 | D3: 2825 | E3: =' TK4 '!E2 -> 2585.6 | F3: =' TK4 '!E14 -> 2587.4 | G3: =' TK4 '!E26 -> 2589.8 | H3: =' TK4 '!E38 -> 2592.2 | I3: =' TK4 '!E50 -> 2594.6 | J3: =' TK4 '!E62 -> 2596.4 | K3: =' TK4 '!E74 -> 2598.8 | L3: =' TK4 '!E86 -> 2601.2 | M3: =' TK4 '!E98 -> 2603.6 | N3: =' TK4 '!E110 -> 2605.4 | O3: =(SUM(E3:N3)/10)/D3 -> 0.91876106
A4: TK5 | B4: FUEL OIL HEADER | C4: 220 | D4: 2825 | E4: ='TK5'!E2 -> 2585.2 | F4: ='TK5'!E14 -> 2587.4 | G4: ='TK5'!E26 -> 2589.8 | H4: ='TK5'!E38 -> 2592.2 | I4: ='TK5'!E50 -> 2594.2 | J4: ='TK5'!E62 -> 2596.4 | K4: ='TK5'!E74 -> 2598.8 | L4: ='TK5'!E86 -> 2601.2 | M4: ='TK5'!E98 -> 2603.6 | N4: ='TK5'!E110 -> 2605.4 | O4: =(SUM(E4:N4)/10)/D4 -> 0.91873274
A5: TK6 | B5: FUEL OIL PS | C5: 210 | D5: 24286 | E5: ='TK6'!E2 -> 22878.4 | F5: ='TK6'!E14 -> 22908.2 | G5: ='TK6'!E26 -> 22935.6 | H5: ='TK6'!E38 -> 22962 | I5: ='TK6'!E50 -> 22988.4 | J5: ='TK6'!E62 -> 23014.8 | K5: ='TK6'!E74 -> 23041.2 | L5: ='TK6'!E86 -> 23067.6 | M5: ='TK6'!E98 -> 23094 | N5: ='TK6'!E110 -> 23120.4 | O5: =(SUM(E5:N5)/10)/D5 -> 0.94709133
A6: TK7 | B6: FUEL OIL PS | C6: 210 | D6: 24286 | E6: ='TK7'!E2 -> 22892.4 | F6: ='TK7'!E14 -> 22921.6 | G6: ='TK7'!E26 -> 22949.2 | H6: ='TK7'!E38 -> 22975.6 | I6: ='TK7'!E50 -> 23002 | J6: ='TK7'!E62 -> 23029.2 | K6: ='TK7'!E74 -> 23055.6 | L6: ='TK7'!E86 -> 23082 | M6: ='TK7'!E98 -> 23109.2 | N6: ='TK7'!E110 -> 23135.6 | O6: =(SUM(E6:N6)/10)/D6 -> 0.9476752
A7: TK11 | B7: FUEL OIL AFT PS | C7: 210 | D7: 11621 | E7: ='TK11'!E2 -> 10841.8 | F7: ='TK11'!E14 -> 10794.6 | G7: ='TK11'!E26 -> 10746.6 | H7: ='TK11'!E38 -> 10697.8 | I7: ='TK11'!E50 -> 10648.2 | J7: ='TK11'!E62 -> 10598.6 | K7: ='TK11'!E74 -> 10549 | L7: ='TK11'!E86 -> 10498.6 | M7: ='TK11'!E98 -> 10449 | N7: ='TK11'!E110 -> 10398.6 | O7: =(SUM(E7:N7)/10)/D7 -> 0.91405903
A8: TK12 | B8: FUEL OIL AFT SB | C8: 210 | D8: 14827 | E8: ='TK12'!E2 -> 13963 | F8: ='TK12'!E14 -> 13915.8 | G8: ='TK12'!E26 -> 13868.6 | H8: ='TK12'!E38 -> 13820.6 | I8: ='TK12'!E50 -> 13772.6 | J8: ='TK12'!E62 -> 13724.6 | K8: ='TK12'!E74 -> 13675.8 | L8: ='TK12'!E86 -> 13625.4 | M8: ='TK12'!E98 -> 13575 | N8: ='TK12'!E110 -> 13524.6 | O8: =(SUM(E8:N8)/10)/D8 -> 0.92713293
A9: TOTAL | D9: =SUM(D3:D8) -> 80670 | E9: =SUM(E3:E8) -> 75746.4 | F9: =SUM(F3:F8) -> 75715 | G9: =SUM(G3:G8) -> 75679.6 | H9: =SUM(H3:H8) -> 75640.4 | I9: =SUM(I3:I8) -> 75600 | J9: =SUM(J3:J8) -> 75560 | K9: =SUM(K3:K8) -> 75519.2 | ... N9: =SUM(N3:N8) -> 75390 | O9: =(SUM(E9:N9)/10)/D9 -> 0.93685509

Sheet  TK4 
A1: sounding | B1: volume lts | D1: SONDAGEM | E1: =SONDAGEM!C3 -> 220
A2: 0 | B2: 729 | D2: VOLUME | E2: =FORECAST(E1,OFFSET(B2:B11,MATCH(E1,A2:A11,1)-1,0,2),OFFSET(A2:A11,MATCH(E1,A2:A11,1)-1,0,2)) -> 2585.6
A3: 25 | B3: 941 | D3: TK4 | E3: FUEL OIL HEADER
A4: 50 | B4: 1153 | D4: trim | E4: -1400
A5: 100 | B5: 1577 | D5: specific wheight ton/m³ | E5: 0.84
A6: 150 | B6: 2001
A7: 200 | B7: 2426
A8: 250 | B8: 2825
A9: 260 | B9: 2825
A13: sounding | B13: volume lts | D13: SONDAGEM | E13: =SONDAGEM!C3 -> 220
A14: 0 | B14: 733 | D14: VOLUME | E14: =FORECAST(E13,OFFSET(B14:B23,MATCH(E13,A14:A23,1)-1,0,2),OFFSET(A14:A23,MATCH(E13,A14:A23,1)-1,0,2)) -> 2587.4
A15: 25 | B15: 945 | D15: TK4 | E15: FUEL OIL HEADER
A16: 50 | B16: 1157 | D16: trim | E16: =E4+200 -> -1200
A17: 100 | B17: 1581 | D17: specific wheight ton/m³ | E17: 0.84
A18: 150 | B18: 2005
A19: 200 | B19: 2429
A20: 250 | B20: 2825
A21: 260 | B21: 2825
A25: sounding | B25: volume lts | D25: SONDAGEM | E25: =SONDAGEM!C3 -> 220
A26: 0 | B26: 736 | D26: VOLUME | E26: =FORECAST(E25,OFFSET(B26:B35,MATCH(E25,A26:A35,1)-1,0,2),OFFSET(A26:A35,MATCH(E25,A26:A35,1)-1,0,2)) -> 2589.8
A27: 25 | B27: 948 | D27: TK4 | E27: FUEL OIL HEADER
A28: 50 | B28: 1160 | D28: trim | E28: =E16+200 -> -1000
A29: 100 | B29: 1585 | D29: specific wheight ton/m³ | E29: 0.84
A30: 150 | B30: 2009
A31: 200 | B31: 2433
A32: 250 | B32: 2825
A33: 260 | B33: 2825
A37: sounding | B37: volume lts | D37: SONDAGEM | E37: =SONDAGEM!C3 -> 220
A38: 0 | B38: 740 | D38: VOLUME | E38: =FORECAST(E37,OFFSET(B38:B47,MATCH(E37,A38:A47,1)-1,0,2),OFFSET(A38:A47,MATCH(E37,A38:A47,1)-1,0,2)) -> 2592.2
A39: 25 | B39: 952 | D39: TK4 | E39: FUEL OIL HEADER
A40: 50 | B40: 1164 | D40: trim | E40: =E28+200 -> -800
A41: 100 | B41: 1588 | D41: specific wheight ton/m³ | E41: 0.84
A42: 150 | B42: 2013
A43: 200 | B43: 2437
A44: 250 | B44: 2825
A45: 260 | B45: 2825
A49: sounding | B49: volume lts | D49: SONDAGEM | E49: =SONDAGEM!C3 -> 220
A50: 0 | B50: 744 | D50: VOLUME | E50: =FORECAST(E49,OFFSET(B50:B59,MATCH(E49,A50:A59,1)-1,0,2),OFFSET(A50:A59,MATCH(E49,A50:A59,1)-1,0,2)) -> 2594.6
A51: 25 | B51: 956 | D51: TK4 | E51: FUEL OIL HEADER
A52: 50 | B52: 1168 | D52: trim | E52: =E40+200 -> -600
...

Sheet TK5
A1: sounding | B1: volume lts | D1: SONDAGEM | E1: =SONDAGEM!C4 -> 220
A2: 0 | B2: 729 | D2: VOLUME | E2: =FORECAST(E1,OFFSET(B2:B11,MATCH(E1,A2:A11,1)-1,0,2),OFFSET(A2:A11,MATCH(E1,A2:A11,1)-1,0,2)) -> 2585.2
A3: 25 | B3: 941 | D3: TK5 | E3: FUEL OIL HEADER
A4: 50 | B4: 1153 | D4: trim | E4: -1400
A5: 100 | B5: 1577 | D5: specific wheight ton/m³ | E5: 0.84
A6: 150 | B6: 2001
A7: 200 | B7: 2426
A8: 250 | B8: 2824
A9: 260 | B9: 2825
A13: sounding | B13: volume lts | D13: SONDAGEM | E13: =SONDAGEM!C4 -> 220
A14: 0 | B14: 733 | D14: VOLUME | E14: =FORECAST(E13,OFFSET(B14:B23,MATCH(E13,A14:A23,1)-1,0,2),OFFSET(A14:A23,MATCH(E13,A14:A23,1)-1,0,2)) -> 2587.4
A15: 25 | B15: 945 | D15: TK5 | E15: FUEL OIL HEADER
A16: 50 | B16: 1157 | D16: trim | E16: =E4+200 -> -1200
A17: 100 | B17: 1581 | D17: specific wheight ton/m³ | E17: 0.84
A18: 150 | B18: 2005
A19: 200 | B19: 2429
A20: 250 | B20: 2825
A21: 260 | B21: 2825
A25: sounding | B25: volume lts | D25: SONDAGEM | E25: =SONDAGEM!C4 -> 220
A26: 0 | B26: 736 | D26: VOLUME | E26: =FORECAST(E25,OFFSET(B26:B35,MATCH(E25,A26:A35,1)-1,0,2),OFFSET(A26:A35,MATCH(E25,A26:A35,1)-1,0,2)) -> 2589.8
A27: 25 | B27: 948 | D27: TK5 | E27: FUEL OIL HEADER
A28: 50 | B28: 1160 | D28: trim | E28: =E16+200 -> -1000
A29: 100 | B29: 1585 | D29: specific wheight ton/m³ | E29: 0.84
A30: 150 | B30: 2009
A31: 200 | B31: 2433
A32: 250 | B32: 2825
A33: 260 | B33: 2825
A37: sounding | B37: volume lts | D37: SONDAGEM | E37: =SONDAGEM!C4 -> 220
A38: 0 | B38: 740 | D38: VOLUME | E38: =FORECAST(E37,OFFSET(B38:B47,MATCH(E37,A38:A47,1)-1,0,2),OFFSET(A38:A47,MATCH(E37,A38:A47,1)-1,0,2)) -> 2592.2
A39: 25 | B39: 952 | D39: TK5 | E39: FUEL OIL HEADER
A40: 50 | B40: 1164 | D40: trim | E40: =E28+200 -> -800
A41: 100 | B41: 1588 | D41: specific wheight ton/m³ | E41: 0.84
A42: 150 | B42: 2013
A43: 200 | B43: 2437
A44: 250 | B44: 2825
A45: 260 | B45: 2825
A49: sounding | B49: volume lts | D49: SONDAGEM | E49: =SONDAGEM!C4 -> 220
A50: 0 | B50: 744 | D50: VOLUME | E50: =FORECAST(E49,OFFSET(B50:B59,MATCH(E49,A50:A59,1)-1,0,2),OFFSET(A50:A59,MATCH(E49,A50:A59,1)-1,0,2)) -> 2594.2
A51: 25 | B51: 956 | D51: TK5 | E51: FUEL OIL HEADER
A52: 50 | B52: 1168 | D52: trim | E52: =E40+200 -> -600
...

Sheet TK6
A1: sounding | B1: volume lts | D1: SONDAGEM | E1: =SONDAGEM!C5 -> 210
A2: 0 | B2: 1101 | D2: VOLUME | E2: =FORECAST(E1,OFFSET(B2:B11,MATCH(E1,A2:A11,1)-1,0,2),OFFSET(A2:A11,MATCH(E1,A2:A11,1)-1,0,2)) -> 22878.4
A3: 25 | B3: 3708 | D3: TK6 | E3: FUEL OIL PS
A4: 50 | B4: 7233 | D4: trim | E4: -1400
A5: 100 | B5: 14953 | D5: specific wheight ton/m³ | E5: 0.84
A6: 150 | B6: 20689
A7: 200 | B7: 22532
A8: 250 | B8: 24264
A9: 260 | B9: 24286
A13: sounding | B13: volume lts | D13: SONDAGEM | E13: =SONDAGEM!C5 -> 210
A14: 0 | B14: 893 | D14: VOLUME | E14: =FORECAST(E13,OFFSET(B14:B23,MATCH(E13,A14:A23,1)-1,0,2),OFFSET(A14:A23,MATCH(E13,A14:A23,1)-1,0,2)) -> 22908.2
A15: 25 | B15: 3450 | D15: TK6 | E15: FUEL OIL PS
A16: 50 | B16: 6974 | D16: trim | E16: =E4+200 -> -1200
A17: 100 | B17: 14712 | D17: specific wheight ton/m³ | E17: 0.84
A18: 150 | B18: 20723
A19: 200 | B19: 22565
A20: 250 | B20: 24281
A21: 260 | B21: 24286
A25: sounding | B25: volume lts | D25: SONDAGEM | E25: =SONDAGEM!C5 -> 210
A26: 0 | B26: 708 | D26: VOLUME | E26: =FORECAST(E25,OFFSET(B26:B35,MATCH(E25,A26:A35,1)-1,0,2),OFFSET(A26:A35,MATCH(E25,A26:A35,1)-1,0,2)) -> 22935.6
A27: 25 | B27: 3195 | D27: TK6 | E27: FUEL OIL PS
A28: 50 | B28: 6727 | D28: trim | E28: =E16+200 -> -1000
A29: 100 | B29: 14471 | D29: specific wheight ton/m³ | E29: 0.84
A30: 150 | B30: 20756
A31: 200 | B31: 22598
A32: 250 | B32: 24286
A33: 260 | B33: 24286
A37: sounding | B37: volume lts | D37: SONDAGEM | E37: =SONDAGEM!C5 -> 210
A38: 0 | B38: 546 | D38: VOLUME | E38: =FORECAST(E37,OFFSET(B38:B47,MATCH(E37,A38:A47,1)-1,0,2),OFFSET(A38:A47,MATCH(E37,A38:A47,1)-1,0,2)) -> 22962
A39: 25 | B39: 2941 | D39: TK6 | E39: FUEL OIL PS
A40: 50 | B40: 6479 | D40: trim | E40: =E28+200 -> -800
A41: 100 | B41: 14230 | D41: specific wheight ton/m³ | E41: 0.84
A42: 150 | B42: 20784
A43: 200 | B43: 22631
A44: 250 | B44: 24286
A45: 260 | B45: 24286
A49: sounding | B49: volume lts | D49: SONDAGEM | E49: =SONDAGEM!C5 -> 210
A50: 0 | B50: 407 | D50: VOLUME | E50: =FORECAST(E49,OFFSET(B50:B59,MATCH(E49,A50:A59,1)-1,0,2),OFFSET(A50:A59,MATCH(E49,A50:A59,1)-1,0,2)) -> 22988.4
A51: 25 | B51: 2690 | D51: TK6 | E51: FUEL OIL PS
A52: 50 | B52: 6233 | D52: trim | E52: =E40+200 -> -600
...

Sheet TK7
A1: sounding | B1: volume lts | D1: SONDAGEM | E1: =SONDAGEM!C6 -> 210
A2: 0 | B2: 1133 | D2: VOLUME | E2: =FORECAST(E1,OFFSET(B2:B11,MATCH(E1,A2:A11,1)-1,0,2),OFFSET(A2:A11,MATCH(E1,A2:A11,1)-1,0,2)) -> 22892.4
A3: 25 | B3: 3764 | D3: TK7 | E3: FUEL OIL SB
A4: 50 | B4: 7289 | D4: trim | E4: -1400
A5: 100 | B5: 15019 | D5: specific wheight ton/m³ | E5: 0.84
A6: 150 | B6: 20707
A7: 200 | B7: 22548
A8: 250 | B8: 24270
A9: 260 | B9: 24286
A13: sounding | B13: volume lts | D13: SONDAGEM | E13: =SONDAGEM!C6 -> 210
A14: 0 | B14: 925 | D14: VOLUME | E14: =FORECAST(E13,OFFSET(B14:B23,MATCH(E13,A14:A23,1)-1,0,2),OFFSET(A14:A23,MATCH(E13,A14:A23,1)-1,0,2)) -> 22921.6
A15: 25 | B15: 3508 | D15: TK7 | E15: FUEL OIL SB
A16: 50 | B16: 7042 | D16: trim | E16: =E4+200 -> -1200
A17: 100 | B17: 14780 | D17: specific wheight ton/m³ | E17: 0.84
A18: 150 | B18: 20741
A19: 200 | B19: 22581
A20: 250 | B20: 24284
A21: 260 | B21: 24286
A25: sounding | B25: volume lts | D25: SONDAGEM | E25: =SONDAGEM!C6 -> 210
A26: 0 | B26: 738 | D26: VOLUME | E26: =FORECAST(E25,OFFSET(B26:B35,MATCH(E25,A26:A35,1)-1,0,2),OFFSET(A26:A35,MATCH(E25,A26:A35,1)-1,0,2)) -> 22949.2
A27: 25 | B27: 3354 | D27: TK7 | E27: FUEL OIL SB
A28: 50 | B28: 6796 | D28: trim | E28: =E16+200 -> -1000
A29: 100 | B29: 14540 | D29: specific wheight ton/m³ | E29: 0.84
A30: 150 | B30: 20773
A31: 200 | B31: 22615
A32: 250 | B32: 24286
A33: 260 | B33: 24286
A37: sounding | B37: volume lts | D37: SONDAGEM | E37: =SONDAGEM!C6 -> 210
A38: 0 | B38: 573 | D38: VOLUME | E38: =FORECAST(E37,OFFSET(B38:B47,MATCH(E37,A38:A47,1)-1,0,2),OFFSET(A38:A47,MATCH(E37,A38:A47,1)-1,0,2)) -> 22975.6
A39: 25 | B39: 3001 | D39: TK7 | E39: FUEL OIL SB
A40: 50 | B40: 6550 | D40: trim | E40: =E28+200 -> -800
A41: 100 | B41: 14300 | D41: specific wheight ton/m³ | E41: 0.84
A42: 150 | B42: 20804
A43: 200 | B43: 22648
A44: 250 | B44: 24286
A45: 260 | B45: 24286
A49: sounding | B49: volume lts | D49: SONDAGEM | E49: =SONDAGEM!C6 -> 210
A50: 0 | B50: 430 | D50: VOLUME | E50: =FORECAST(E49,OFFSET(B50:B59,MATCH(E49,A50:A59,1)-1,0,2),OFFSET(A50:A59,MATCH(E49,A50:A59,1)-1,0,2)) -> 23002
A51: 25 | B51: 2749 | D51: TK7 | E51: FUEL OIL SB
A52: 50 | B52: 6304 | D52: trim | E52: =E40+200 -> -600
...

Sheet TK11
A1: sounding | B1: volume lts | D1: SONDAGEM | E1: =SONDAGEM!C7 -> 210
A2: 0 | B2: 22 | D2: VOLUME | E2: =FORECAST(E1,OFFSET(B2:B11,MATCH(E1,A2:A11,1)-1,0,2),OFFSET(A2:A11,MATCH(E1,A2:A11,1)-1,0,2)) -> 10841.8
A3: 25 | B3: 311 | D3: TK11 | E3: FUEL OIL AFT PS
A4: 50 | B4: 1077 | D4: trim | E4: -1400
A5: 100 | B5: 3742 | D5: specific wheight ton/m³ | E5: 0.84
A6: 150 | B6: 7254
A7: 200 | B7: 10647
A8: 250 | B8: 11621
A9: 260 | B9: 11621
A13: sounding | B13: volume lts | D13: SONDAGEM | E13: =SONDAGEM!C7 -> 210
A14: 0 | B14: 22 | D14: VOLUME | E14: =FORECAST(E13,OFFSET(B14:B23,MATCH(E13,A14:A23,1)-1,0,2),OFFSET(A14:A23,MATCH(E13,A14:A23,1)-1,0,2)) -> 10794.6
A15: 25 | B15: 306 | D15: TK11 | E15: FUEL OIL AFT PS
A16: 50 | B16: 1057 | D16: trim | E16: =E4+200 -> -1200
A17: 100 | B17: 3674 | D17: specific wheight ton/m³ | E17: 0.84
A18: 150 | B18: 7189
A19: 200 | B19: 10588
A20: 250 | B20: 11621
A21: 260 | B21: 11621
A25: sounding | B25: volume lts | D25: SONDAGEM | E25: =SONDAGEM!C7 -> 210
A26: 0 | B26: 21 | D26: VOLUME | E26: =FORECAST(E25,OFFSET(B26:B35,MATCH(E25,A26:A35,1)-1,0,2),OFFSET(A26:A35,MATCH(E25,A26:A35,1)-1,0,2)) -> 10746.6
A27: 25 | B27: 302 | D27: TK11 | E27: FUEL OIL AFT PS
A28: 50 | B28: 1040 | D28: trim | E28: =E16+200 -> -1000
A29: 100 | B29: 3610 | D29: specific wheight ton/m³ | E29: 0.84
A30: 150 | B30: 7124
A31: 200 | B31: 10528
A32: 250 | B32: 11621
A33: 260 | B33: 11621
A37: sounding | B37: volume lts | D37: SONDAGEM | E37: =SONDAGEM!C7 -> 210
A38: 0 | B38: 22 | D38: VOLUME | E38: =FORECAST(E37,OFFSET(B38:B47,MATCH(E37,A38:A47,1)-1,0,2),OFFSET(A38:A47,MATCH(E37,A38:A47,1)-1,0,2)) -> 10697.8
A39: 25 | B39: 299 | D39: TK11 | E39: FUEL OIL AFT PS
A40: 50 | B40: 1024 | D40: trim | E40: =E28+200 -> -800
A41: 100 | B41: 3550 | D41: specific wheight ton/m³ | E41: 0.84
A42: 150 | B42: 7059
A43: 200 | B43: 10467
A44: 250 | B44: 11621
A45: 260 | B45: 11621
A49: sounding | B49: volume lts | D49: SONDAGEM | E49: =SONDAGEM!C7 -> 210
A50: 0 | B50: 22 | D50: VOLUME | E50: =FORECAST(E49,OFFSET(B50:B59,MATCH(E49,A50:A59,1)-1,0,2),OFFSET(A50:A59,MATCH(E49,A50:A59,1)-1,0,2)) -> 10648.2
A51: 25 | B51: 296 | D51: TK11 | E51: FUEL OIL AFT PS
A52: 50 | B52: 1010 | D52: trim | E52: =E40+200 -> -600
...

Sheet TK12
A1: sounding | B1: volume lts | D1: SONDAGEM | E1: =SONDAGEM!C8 -> 210
A2: 0 | B2: 30 | D2: VOLUME | E2: =FORECAST(E1,OFFSET(B2:B11,MATCH(E1,A2:A11,1)-1,0,2),OFFSET(A2:A11,MATCH(E1,A2:A11,1)-1,0,2)) -> 13963
A3: 25 | B3: 497 | D3: TK12 | E3: FUEL OIL AFT SB
A4: 50 | B4: 1646 | D4: trim | E4: -1400
A5: 100 | B5: 5155 | D5: specific wheight ton/m³ | E5: 0.84
A6: 150 | B6: 9561
A7: 200 | B7: 13747
A8: 250 | B8: 14827
A9: 260 | B9: 14827
A13: sounding | B13: volume lts | D13: SONDAGEM | E13: =SONDAGEM!C8 -> 210
A14: 0 | B14: 35 | D14: VOLUME | E14: =FORECAST(E13,OFFSET(B14:B23,MATCH(E13,A14:A23,1)-1,0,2),OFFSET(A14:A23,MATCH(E13,A14:A23,1)-1,0,2)) -> 13915.8
A15: 25 | B15: 511 | D15: TK12 | E15: FUEL OIL AFT SB
A16: 50 | B16: 1654 | D16: trim | E16: =E4+200 -> -1200
A17: 100 | B17: 5120 | D17: specific wheight ton/m³ | E17: 0.84
A18: 150 | B18: 9531
A19: 200 | B19: 13688
A20: 250 | B20: 14827
A21: 260 | B21: 14827
A25: sounding | B25: volume lts | D25: SONDAGEM | E25: =SONDAGEM!C8 -> 210
A26: 0 | B26: 39 | D26: VOLUME | E26: =FORECAST(E25,OFFSET(B26:B35,MATCH(E25,A26:A35,1)-1,0,2),OFFSET(A26:A35,MATCH(E25,A26:A35,1)-1,0,2)) -> 13868.6
A27: 25 | B27: 525 | D27: TK12 | E27: FUEL OIL AFT SB
A28: 50 | B28: 1663 | D28: trim | E28: =E16+200 -> -1000
A29: 100 | B29: 5089 | D29: specific wheight ton/m³ | E29: 0.84
A30: 150 | B30: 9502
A31: 200 | B31: 13629
A32: 250 | B32: 14827
A33: 260 | B33: 14827
A37: sounding | B37: volume lts | D37: SONDAGEM | E37: =SONDAGEM!C8 -> 210
A38: 0 | B38: 44 | D38: VOLUME | E38: =FORECAST(E37,OFFSET(B38:B47,MATCH(E37,A38:A47,1)-1,0,2),OFFSET(A38:A47,MATCH(E37,A38:A47,1)-1,0,2)) -> 13820.6
A39: 25 | B39: 541 | D39: TK12 | E39: FUEL OIL AFT SB
A40: 50 | B40: 1674 | D40: trim | E40: =E28+200 -> -800
A41: 100 | B41: 5061 | D41: specific wheight ton/m³ | E41: 0.84
A42: 150 | B42: 9472
A43: 200 | B43: 13569
A44: 250 | B44: 14827
A45: 260 | B45: 14827
A49: sounding | B49: volume lts | D49: SONDAGEM | E49: =SONDAGEM!C8 -> 210
A50: 0 | B50: 51 | D50: VOLUME | E50: =FORECAST(E49,OFFSET(B50:B59,MATCH(E49,A50:A59,1)-1,0,2),OFFSET(A50:A59,MATCH(E49,A50:A59,1)-1,0,2)) -> 13772.6
A51: 25 | B51: 558 | D51: TK12 | E51: FUEL OIL AFT SB
A52: 50 | B52: 1686 | D52: trim | E52: =E40+200 -> -600
...
