Workbook

Sheet SONDAGEM
A1: SONDAGEM REB CHILE E HOLANDA | D1: TRIM & VOLUME LTS | G1: %
A3: TANQUE | B3: SONDAGEM CM | C3: CAPACIDADE | D3: TRIM ZERO | E3: 5 GRAUS NEG | F3: 5 GRAUS POS
A4: TK1 BB | B4: 10 | C4: 9203 | D4: ='TK1BB '!N5 -> 53 | E4: ='TK1BB '!N50 -> 52 | F4: ='TK1BB '!N93 -> 55 | G4: =(SUM(D4:F4)/3)/C4 -> 0.0057952117
A5: TK1 BE | B5: 0 | C5: 9203 | D5: ='TK 1 BE'!N5 -> 17 | E5: ='TK 1 BE'!N50 -> 17 | F5: ='TK 1 BE'!N94 -> 17 | G5: =(SUM(D5:F5)/3)/C5 -> 0.0018472237
A6: TK 2 CENTRAL | B6: 0 | C6: 12315 | D6: ='TK 2 CTL'!N5 -> 1225 | E6: ='TK 2 CTL'!N20 -> 1286 | F6: ='TK 2 CTL'!N35 -> 1165 | G6: =(SUM(D6:F6)/3)/C6 -> 0.099499256
A7: TK 6 BB | B7: 0 | C7: 13981 | D7: ='TK6 BB'!N5 -> 6 | E7: ='TK6 BB'!N33 -> 6 | F7: ='TK6 BB'!N60 -> 6 | G7: =(SUM(D7:F7)/3)/C7 -> 0.00042915385
A8: TK 6 BE | B8: 0 | C8: 11694 | D8: ='TK6 BE'!N5 -> 8 | E8: ='TK6 BE'!N33 -> 8 | F8: ='TK6 BE'!N62 -> 7 | G8: =(SUM(D8:F8)/3)/C8 -> 0.00065560686
A9: TOTAL | C9: =SUM(C4:C8) -> 56396 | D9: =SUM(D4:D8) -> 1309 | E9: =SUM(E4:E8) -> 1369 | F9: =SUM(F4:F8) -> 1250 | G9: =(SUM(D9:F9)/3)/C9 -> 0.023216777

Sheet TK1BB 
B3: 0 | C3: 1 | D3: 2 | E3: 3 | F3: 4 | G3: 5 | H3: 6 | I3: 7 | J3: 8 | K3: 9 | M3: TRIM | N3: ZERO
A4: 0 | B4: 17 | C4: 19 | D4: 22 | E4: 25 | F4: 29 | G4: 32 | H4: 36 | I4: 40 | J4: 44 | K4: 49 | M4: SONDAGEM | N4: VOLUME LTS
A5: 10 | B5: 53 | C5: 58 | D5: 63 | E5: 69 | F5: 74 | G5: 80 | H5: 86 | I5: 92 | J5: 99 | K5: 106 | M5: =SONDAGEM!B4 -> 10 | N5: =OFFSET(B4,MATCH(M7,A4:A43,0)-1,MATCH(N7,B3:K3,0)-1) -> 53
A6: 20 | B6: 113 | C6: 120 | D6: 127 | E6: 135 | F6: 143 | G6: 151 | H6: 159 | I6: 168 | J6: 177 | K6: 186 | M6: =M5-N6 -> 10 | N6: =VALUE(RIGHT(M5,1)) -> 0
A7: 30 | B7: 196 | C7: 205 | D7: 215 | E7: 225 | F7: 235 | G7: 245 | H7: 256 | I7: 266 | J7: 277 | K7: 288 | M7: =M6 -> 10 | N7: =N6 -> 0
A8: 40 | B8: 299 | C8: 310 | D8: 321 | E8: 332 | F8: 343 | G8: 354 | H8: 366 | I8: 377 | J8: 389 | K8: 400
A9: 50 | B9: 412 | C9: 424 | D9: 435 | E9: 447 | F9: 459 | G9: 471 | H9: 484 | I9: 496 | J9: 509 | K9: 522
A10: 60 | B10: 535 | C10: 548 | D10: 561 | E10: 575 | F10: 588 | G10: 602 | H10: 615 | I10: 629 | J10: 643 | K10: 657
A11: 70 | B11: 671 | C11: 685 | D11: 699 | E11: 714 | F11: 728 | G11: 743 | H11: 757 | I11: 772 | J11: 787 | K11: 801
A12: 80 | B12: 816 | C12: 831 | D12: 846 | E12: 862 | F12: 877 | G12: 892 | H12: 908 | I12: 923 | J12: 939 | K12: 955
A13: 90 | B13: 970 | C13: 986 | D13: 1002 | E13: 1018 | F13: 1034 | G13: 1050 | H13: 1066 | I13: 1083 | J13: 1099 | K13: 1115
A14: 100 | B14: 1132 | C14: 1148 | D14: 1165 | E14: 1182 | F14: 1199 | G14: 1215 | H14: 1232 | I14: 1249 | J14: 1266 | K14: 1283
A15: 110 | B15: 1300 | C15: 1318 | D15: 1335 | E15: 1352 | F15: 1369 | G15: 1387 | H15: 1404 | I15: 1422 | J15: 1440 | K15: 1459
A16: 120 | B16: 1478 | C16: 1497 | D16: 1516 | E16: 1535 | F16: 1554 | G16: 1573 | H16: 1593 | I16: 1612 | J16: 1631 | K16: 1651
A17: 130 | B17: 1670 | C17: 1690 | D17: 1710 | E17: 1729 | F17: 1749 | G17: 1769 | H17: 1789 | I17: 1809 | J17: 1828 | K17: 1848
A18: 140 | B18: 1869 | C18: 1889 | D18: 1909 | E18: 1929 | F18: 1949 | G18: 1970 | H18: 1990 | I18: 2010 | J18: 2031 | K18: 2052
A19: 150 | B19: 2072 | C19: 2093 | D19: 2113 | E19: 2134 | F19: 2155 | G19: 2176 | H19: 2197 | I19: 2218 | J19: 2239 | K19: 2260
... A42: 380 | B42: 8714 | C42: 8748 | D42: 8781 | E42: 8815 | F42: 8848 | G42: 8882 | H42: 8915 | I42: 8949 | J42: 8982 | K42: 9015
A43: 390 | B43: 9049 | C43: 9079 | D43: 9106 | E43: 9130 | F43: 9203
B48: 0 | C48: 1 | D48: 2 | E48: 3 | F48: 4 | G48: 5 | H48: 6 | I48: 7 | J48: 8 | K48: 9 | M48: TRIM POSITIVO | N48: 5 GRAUS POSITIVO
A49: 0 | B49: 17 | C49: 19 | D49: 22 | E49: 25 | F49: 28 | G49: 32 | H49: 35 | I49: 39 | J49: 43 | K49: 48 | M49: SONDAGEM | N49: VOLUME LTS
A50: 10 | B50: 52 | C50: 57 | D50: 62 | E50: 67 | F50: 73 | G50: 78 | H50: 84 | I50: 90 | J50: 97 | K50: 103 | M50: =SONDAGEM!B4 -> 10 | N50: =OFFSET(B49,MATCH(M52,A49:A88,0)-1,MATCH(N52,B48:K48,0)-1) -> 52
A51: 20 | B51: 110 | C51: 117 | D51: 124 | E51: 132 | F51: 139 | G51: 147 | H51: 155 | I51: 164 | J51: 172 | K51: 181 | M51: =M50-N51 -> 10 | N51: =VALUE(RIGHT(M50,1)) -> 0
A52: 30 | B52: 190 | C52: 200 | D52: 209 | E52: 219 | F52: 229 | G52: 239 | H52: 249 | I52: 260 | J52: 270 | K52: 281 | M52: =M51 -> 10 | N52: =N51 -> 0
A53: 40 | B53: 292 | C53: 303 | D53: 314 | E53: 325 | F53: 336 | G53: 347 | H53: 358 | I53: 370 | J53: 381 | K53: 393
A54: 50 | B54: 404 | C54: 416 | D54: 428 | E54: 440 | F54: 452 | G54: 464 | H54: 476 | I54: 488 | J54: 501 | K54: 514
A55: 60 | B55: 527 | C55: 540 | D55: 553 | E55: 567 | F55: 580 | G55: 593 | H55: 607 | I55: 621 | J55: 635 | K55: 648
A56: 70 | B56: 662 | C56: 677 | D56: 691 | E56: 705 | F56: 719 | G56: 734 | H56: 748 | I56: 763 | J56: 777 | K56: 792
A57: 80 | B57: 807 | C57: 822 | D57: 837 | E57: 852 | F57: 867 | G57: 883 | H57: 898 | I57: 914 | J57: 929 | K57: 945
A58: 90 | B58: 960 | C58: 976 | D58: 992 | E58: 1008 | F58: 1024 | G58: 1040 | H58: 1056 | I58: 1072 | J58: 1089 | K58: 1105
A59: 100 | B59: 1122 | C59: 1138 | D59: 1155 | E59: 1171 | F59: 1188 | G59: 1205 | H59: 1222 | I59: 1238 | J59: 1255 | K59: 1272
A60: 110 | B60: 1290 | C60: 1307 | D60: 1324 | E60: 1341 | F60: 1358 | G60: 1376 | H60: 1393 | I60: 1411 | J60: 1429 | K60: 1448
A61: 120 | B61: 1466 | C61: 1485 | D61: 1504 | E61: 1524 | F61: 1543 | G61: 1562 | H61: 1581 | I61: 1600 | J61: 1620 | K61: 1639
A62: 130 | B62: 1659 | C62: 1678 | D62: 1698 | E62: 1717 | F62: 1737 | G62: 1757 | H62: 1777 | I62: 1797 | J62: 1817 | K62: 1836
A63: 140 | B63: 1857 | C63: 1877 | D63: 1897 | E63: 1917 | F63: 1937 | G63: 1957 | H63: 1978 | I63: 1998 | J63: 2019 | K63: 2039
A64: 150 | B64: 2060 | C64: 2080 | D64: 2101 | E64: 2122 | F64: 2143 | G64: 2163 | H64: 2184 | I64: 2205 | J64: 2226 | K64: 2247
... A87: 380 | B87: 8696 | C87: 8730 | D87: 8763 | E87: 8796 | F87: 8830 | G87: 8863 | H87: 8897 | I87: 8930 | J87: 8964 | K87: 8997
A88: 390 | B88: 9031 | C88: 9062 | D88: 9092 | E88: 9117 | F88: 9203
B91: 0 | C91: 1 | D91: 2 | E91: 3 | F91: 4 | G91: 5 | H91: 6 | I91: 7 | J91: 8 | K91: 9 | M91: TRIM | N91: 5 GRAUS NEGATIVO
A92: 0 | B92: 17 | C92: 20 | D92: 23 | E92: 26 | F92: 29 | G92: 33 | H92: 37 | I92: 41 | J92: 45 | K92: 50 | M92: SONDAGEM | N92: VOLUME LTS
...

Sheet TK 1 BE
B3: 0 | C3: 1 | D3: 2 | E3: 3 | F3: 4 | G3: 5 | H3: 6 | I3: 7 | J3: 8 | K3: 9 | M3: TRIM | N3: ZERO
A4: 0 | B4: 17 | C4: 19 | D4: 22 | E4: 25 | F4: 29 | G4: 32 | H4: 36 | I4: 40 | J4: 44 | K4: 49 | M4: SONDAGEM | N4: VOLUME LTS
A5: 10 | B5: 53 | C5: 58 | D5: 63 | E5: 69 | F5: 74 | G5: 80 | H5: 86 | I5: 92 | J5: 99 | K5: 106 | M5: =SONDAGEM!B5 -> 0 | N5: =OFFSET(B4,MATCH(M7,A4:A43,0)-1,MATCH(N7,B3:K3,0)-1) -> 17
A6: 20 | B6: 113 | C6: 120 | D6: 127 | E6: 135 | F6: 143 | G6: 151 | H6: 159 | I6: 168 | J6: 177 | K6: 186 | M6: =M5-N6 -> 0 | N6: =VALUE(RIGHT(M5,1)) -> 0
A7: 30 | B7: 196 | C7: 205 | D7: 215 | E7: 225 | F7: 235 | G7: 245 | H7: 256 | I7: 266 | J7: 277 | K7: 288 | M7: =M6 -> 0 | N7: =N6 -> 0
A8: 40 | B8: 299 | C8: 310 | D8: 321 | E8: 332 | F8: 343 | G8: 354 | H8: 366 | I8: 377 | J8: 389 | K8: 400
A9: 50 | B9: 412 | C9: 424 | D9: 435 | E9: 447 | F9: 459 | G9: 471 | H9: 484 | I9: 496 | J9: 509 | K9: 522
A10: 60 | B10: 535 | C10: 548 | D10: 561 | E10: 575 | F10: 588 | G10: 602 | H10: 615 | I10: 629 | J10: 643 | K10: 657
A11: 70 | B11: 671 | C11: 685 | D11: 699 | E11: 714 | F11: 728 | G11: 743 | H11: 757 | I11: 772 | J11: 787 | K11: 801
A12: 80 | B12: 816 | C12: 831 | D12: 846 | E12: 862 | F12: 877 | G12: 892 | H12: 908 | I12: 923 | J12: 939 | K12: 955
A13: 90 | B13: 970 | C13: 986 | D13: 1002 | E13: 1018 | F13: 1034 | G13: 1050 | H13: 1066 | I13: 1083 | J13: 1099 | K13: 1115
A14: 100 | B14: 1132 | C14: 1148 | D14: 1165 | E14: 1182 | F14: 1199 | G14: 1215 | H14: 1232 | I14: 1249 | J14: 1266 | K14: 1283
A15: 110 | B15: 1300 | C15: 1318 | D15: 1335 | E15: 1352 | F15: 1369 | G15: 1387 | H15: 1404 | I15: 1422 | J15: 1440 | K15: 1459
A16: 120 | B16: 1478 | C16: 1497 | D16: 1516 | E16: 1535 | F16: 1554 | G16: 1573 | H16: 1593 | I16: 1612 | J16: 1631 | K16: 1651
A17: 130 | B17: 1670 | C17: 1690 | D17: 1710 | E17: 1729 | F17: 1749 | G17: 1769 | H17: 1789 | I17: 1809 | J17: 1828 | K17: 1848
A18: 140 | B18: 1869 | C18: 1889 | D18: 1909 | E18: 1929 | F18: 1949 | G18: 1970 | H18: 1990 | I18: 2010 | J18: 2031 | K18: 2052
A19: 150 | B19: 2072 | C19: 2093 | D19: 2113 | E19: 2134 | F19: 2155 | G19: 2176 | H19: 2197 | I19: 2218 | J19: 2239 | K19: 2260
... A42: 380 | B42: 8714 | C42: 8748 | D42: 8781 | E42: 8815 | F42: 8848 | G42: 8882 | H42: 8915 | I42: 8949 | J42: 8982 | K42: 9015
A43: 390 | B43: 9049 | C43: 9079 | D43: 9106 | E43: 9130 | F43: 9203
B48: 0 | C48: 1 | D48: 2 | E48: 3 | F48: 4 | G48: 5 | H48: 6 | I48: 7 | J48: 8 | K48: 9 | M48: TRIM POSITIVO | N48: 5 GRAUS POSITIVO
A49: 0 | B49: 17 | C49: 19 | D49: 22 | E49: 25 | F49: 28 | G49: 32 | H49: 35 | I49: 39 | J49: 43 | K49: 48 | M49: SONDAGEM | N49: VOLUME LTS
A50: 10 | B50: 52 | C50: 57 | D50: 62 | E50: 67 | F50: 73 | G50: 78 | H50: 84 | I50: 90 | J50: 97 | K50: 103 | M50: =SONDAGEM!B5 -> 0 | N50: =OFFSET(B49,MATCH(M52,A49:A89,0)-1,MATCH(N52,B48:K48,0)-1) -> 17
A51: 20 | B51: 110 | C51: 117 | D51: 124 | E51: 132 | F51: 139 | G51: 147 | H51: 155 | I51: 164 | J51: 172 | K51: 181 | M51: =M50-N51 -> 0 | N51: =VALUE(RIGHT(M50,1)) -> 0
A52: 30 | B52: 190 | C52: 200 | D52: 209 | E52: 219 | F52: 229 | G52: 239 | H52: 249 | I52: 260 | J52: 270 | K52: 281 | M52: =M51 -> 0 | N52: =N51 -> 0
A53: 40 | B53: 292 | C53: 303 | D53: 314 | E53: 325 | F53: 336 | G53: 347 | H53: 358 | I53: 370 | J53: 381 | K53: 393
A54: 50 | B54: 404 | C54: 416 | D54: 428 | E54: 440 | F54: 452 | G54: 464 | H54: 476 | I54: 488 | J54: 501 | K54: 514
A55: 60 | B55: 527 | C55: 540 | D55: 553 | E55: 567 | F55: 580 | G55: 593 | H55: 607 | I55: 621 | J55: 635 | K55: 648
A56: 70 | B56: 662 | C56: 677 | D56: 691 | E56: 705 | F56: 719 | G56: 734 | H56: 748 | I56: 763 | J56: 777 | K56: 792
A57: 80 | B57: 807 | C57: 822 | D57: 837 | E57: 852 | F57: 867 | G57: 883 | H57: 898 | I57: 914 | J57: 929 | K57: 945
A58: 90 | B58: 960 | C58: 976 | D58: 992 | E58: 1008 | F58: 1024 | G58: 1040 | H58: 1056 | I58: 1072 | J58: 1089 | K58: 1105
A59: 100 | B59: 1122 | C59: 1138 | D59: 1155 | E59: 1171 | F59: 1188 | G59: 1205 | H59: 1222 | I59: 1238 | J59: 1255 | K59: 1272
A60: 110 | B60: 1290 | C60: 1307 | D60: 1324 | E60: 1341 | F60: 1358 | G60: 1376 | H60: 1393 | I60: 1411 | J60: 1429 | K60: 1448
A61: 120 | B61: 1466 | C61: 1485 | D61: 1504 | E61: 1524 | F61: 1543 | G61: 1562 | H61: 1581 | I61: 1600 | J61: 1620 | K61: 1639
A62: 130 | B62: 1659 | C62: 1678 | D62: 1698 | E62: 1717 | F62: 1737 | G62: 1757 | H62: 1777 | I62: 1797 | J62: 1817 | K62: 1836
A63: 140 | B63: 1857 | C63: 1877 | D63: 1897 | E63: 1917 | F63: 1937 | G63: 1957 | H63: 1978 | I63: 1998 | J63: 2019 | K63: 2039
A64: 150 | B64: 2060 | C64: 2080 | D64: 2101 | E64: 2122 | F64: 2143 | G64: 2163 | H64: 2184 | I64: 2205 | J64: 2226 | K64: 2247
... A87: 380 | B87: 8696 | C87: 8730 | D87: 8763 | E87: 8796 | F87: 8830 | G87: 8863 | H87: 8897 | I87: 8930 | J87: 8964 | K87: 8997
A88: 390 | B88: 9031 | C88: 9062 | D88: 9092 | E88: 9117 | F88: 9203
A89: 394 | B89: 9203
B92: 0 | C92: 1 | D92: 2 | E92: 3 | F92: 4 | G92: 5 | H92: 6 | I92: 7 | J92: 8 | K92: 9 | M92: TRIM | N92: 5 GRAUS NEGATIVO
...

Sheet TK 2 CTL
B3: 0 | C3: 1 | D3: 2 | E3: 3 | F3: 4 | G3: 5 | H3: 6 | I3: 7 | J3: 8 | K3: 9 | M3: TRIM | N3: ZERO
A4: 0 | B4: 1225 | C4: 1292 | D4: 1361 | E4: 1431 | F4: 1502 | G4: 1575 | H4: 1650 | I4: 1726 | J4: 1804 | K4: 1884 | M4: SONDAGEM | N4: VOLUME LTS
A5: 10 | B5: 1965 | C5: 2047 | D5: 2131 | E5: 2217 | F5: 2304 | G5: 2392 | H5: 2482 | I5: 2574 | J5: 2667 | K5: 2761 | M5: =SONDAGEM!B6 -> 0 | N5: =OFFSET($B$4,MATCH($M$7,$A$4:$A$14,0)-1,MATCH($N$7,$B$3:$K$3,0)-1) -> 1225
A6: 20 | B6: 2857 | C6: 2955 | D6: 3053 | E6: 3154 | F6: 3256 | G6: 3358 | H6: 3462 | I6: 3567 | J6: 3673 | K6: 3780 | M6: =M5-N6 -> 0 | N6: =VALUE(RIGHT(M5,1)) -> 0
A7: 30 | B7: 3888 | C7: 3996 | D7: 4105 | E7: 4215 | F7: 4325 | G7: 4435 | H7: 4546 | I7: 4657 | J7: 4768 | K7: 4879 | M7: =M6 -> 0 | N7: =N6 -> 0
A8: 40 | B8: 4990 | C8: 5101 | D8: 5212 | E8: 5323 | F8: 5435 | G8: 5546 | H8: 5657 | I8: 5768 | J8: 5879 | K8: 5990
A9: 50 | B9: 6101 | C9: 6213 | D9: 6324 | E9: 6435 | F9: 6546 | G9: 6657 | H9: 6768 | I9: 6880 | J9: 6991 | K9: 7102
A10: 60 | B10: 7213 | C10: 7324 | D10: 7435 | E10: 7546 | F10: 7658 | G10: 7769 | H10: 7880 | I10: 7991 | J10: 8102 | K10: 8213
A11: 70 | B11: 8325 | C11: 8436 | D11: 8547 | E11: 8658 | F11: 8769 | G11: 8880 | H11: 8991 | I11: 9103 | J11: 9214 | K11: 9325
A12: 80 | B12: 9436 | C12: 9547 | D12: 9658 | E12: 9770 | F12: 9881 | G12: 9992 | H12: 10103 | I12: 10214 | J12: 10325 | K12: 10436
A13: 90 | B13: 10548 | C13: 10659 | D13: 10770 | E13: 10881 | F13: 10992 | G13: 11103 | H13: 11215 | I13: 11326 | J13: 11437 | K13: 11548
A14: 100 | B14: 11659 | C14: 11770 | D14: 11881 | E14: 11993 | F14: 12104 | G14: 12215 | H14: 12315
B18: 0 | C18: 1 | D18: 2 | E18: 3 | F18: 4 | G18: 5 | H18: 6 | I18: 7 | J18: 8 | K18: 9 | M18: TRIM | N18: 5 GRAUS NEGATIVO
A19: 0 | B19: 1286 | C19: 1353 | D19: 1421 | E19: 1491 | F19: 1563 | G19: 1636 | H19: 1711 | I19: 1787 | J19: 1864 | K19: 1943 | M19: SONDAGEM | N19: VOLUME LTS
A20: 10 | B20: 2024 | C20: 2106 | D20: 2189 | E20: 2274 | F20: 2360 | G20: 2448 | H20: 2537 | I20: 2628 | J20: 2720 | K20: 2814 | M20: =SONDAGEM!B6 -> 0 | N20: =OFFSET(B19,MATCH(M22,A19:A29,0)-1,MATCH(N22,B18:K18,0)-1) -> 1286
A21: 20 | B21: 2909 | C21: 3005 | D21: 3103 | E21: 3202 | F21: 3303 | G21: 3405 | H21: 3508 | I21: 3612 | J21: 3717 | K21: 3823 | M21: =M20-N21 -> 0 | N21: =VALUE(RIGHT(M20,1)) -> 0
A22: 30 | B22: 3930 | C22: 4038 | D22: 4146 | E22: 4255 | F22: 4365 | G22: 4475 | H22: 4585 | I22: 4696 | J22: 4807 | K22: 4918 | M22: =M21 -> 0 | N22: =N21 -> 0
A23: 40 | B23: 5029 | C23: 5140 | D23: 5251 | E23: 5362 | F23: 5473 | G23: 5584 | H23: 5696 | I23: 5807 | J23: 5918 | K23: 6029
A24: 50 | B24: 6140 | C24: 6251 | D24: 6363 | E24: 6474 | F24: 6585 | G24: 6696 | H24: 6807 | I24: 6918 | J24: 7029 | K24: 7141
A25: 60 | B25: 7252 | C25: 7363 | D25: 7474 | E25: 7585 | F25: 7696 | G25: 7808 | H25: 7919 | I25: 8030 | J25: 8141 | K25: 8252
A26: 70 | B26: 8363 | C26: 8474 | D26: 8586 | E26: 8697 | F26: 8808 | G26: 8919 | H26: 9030 | I26: 9141 | J26: 9253 | K26: 9364
A27: 80 | B27: 9475 | C27: 9586 | D27: 9697 | E27: 9808 | F27: 9919 | G27: 10031 | H27: 10142 | I27: 10253 | J27: 10364 | K27: 10475
A28: 90 | B28: 10586 | C28: 10698 | D28: 10809 | E28: 10920 | F28: 11031 | G28: 11142 | H28: 11253 | I28: 11364 | J28: 11476 | K28: 11587
A29: 100 | B29: 11698 | C29: 11809 | D29: 11920 | E29: 12031 | F29: 12143 | G29: 12238 | H29: 12315
B33: 0 | C33: 1 | D33: 2 | E33: 3 | F33: 4 | G33: 5 | H33: 6 | I33: 7 | J33: 8 | K33: 9 | M33: TRIM POSITIVO | N33: 5 GRAUS POSITIVO
A34: 0 | B34: 1165 | C34: 1231 | D34: 1300 | E34: 1370 | F34: 1442 | G34: 1515 | H34: 1590 | I34: 1666 | J34: 1745 | K34: 1824 | M34: SONDAGEM | N34: VOLUME LTS
A35: 10 | B35: 1906 | C35: 1989 | D35: 2074 | E35: 2160 | F35: 2247 | G35: 2337 | H35: 2428 | I35: 2520 | J35: 2614 | K35: 2709 | M35: =SONDAGEM!B6 -> 0 | N35: =OFFSET(B34,MATCH(M37,A34:A44,0)-1,MATCH(N37,B33:K33,0)-1) -> 1165
A36: 20 | B36: 2806 | C36: 2905 | D36: 3005 | E36: 3106 | F36: 3209 | G36: 3313 | H36: 3418 | I36: 3524 | J36: 3630 | K36: 3738 | M36: =M35-N36 -> 0 | N36: =VALUE(RIGHT(M35,1)) -> 0
A37: 30 | B37: 3846 | C37: 3955 | D37: 4065 | E37: 4175 | F37: 4285 | G37: 4396 | H37: 4507 | I37: 4618 | J37: 4729 | K37: 4840 | M37: =M36 -> 0 | N37: =N36 -> 0
A38: 40 | B38: 4951 | C38: 5062 | D38: 5173 | E38: 5285 | F38: 5396 | G38: 5507 | H38: 5618 | I38: 5729 | J38: 5840 | K38: 5951
A39: 50 | B39: 6063 | C39: 6174 | D39: 6285 | E39: 6396 | F39: 6507 | G39: 6618 | H39: 6730 | I39: 6841 | J39: 6952 | K39: 7063
A40: 60 | B40: 7174 | C40: 7285 | D40: 7396 | E40: 7508 | F40: 7619 | G40: 7730 | H40: 7841 | I40: 7952 | J40: 8063 | K40: 8175
A41: 70 | B41: 8286 | C41: 8397 | D41: 8508 | E41: 8619 | F41: 8730 | G41: 8841 | H41: 8953 | I41: 9064 | J41: 9175 | K41: 9286
A42: 80 | B42: 9397 | C42: 9508 | D42: 9620 | E42: 9731 | F42: 9842 | G42: 9953 | H42: 10064 | I42: 10175 | J42: 10286 | K42: 10398
A43: 90 | B43: 10509 | C43: 10620 | D43: 10731 | E43: 10842 | F43: 10953 | G43: 11065 | H43: 11176 | I43: 11287 | J43: 11398 | K43: 11509
A44: 100 | B44: 11620 | C44: 11731 | D44: 11843 | E44: 11954 | F44: 12069 | G44: 12175 | H44: 12315

Sheet TK6 BB
B3: 0 | C3: 1 | D3: 2 | E3: 3 | F3: 4 | G3: 5 | H3: 6 | I3: 7 | J3: 8 | K3: 9 | M3: TRIM | N3: ZERO
A4: 0 | B4: 6 | C4: 9 | D4: 12 | E4: 16 | F4: 21 | G4: 27 | H4: 34 | I4: 41 | J4: 49 | K4: 58 | M4: SONDAGEM | N4: VOLUME LTS
A5: 10 | B5: 68 | C5: 79 | D5: 91 | E5: 104 | F5: 118 | G5: 133 | H5: 150 | I5: 167 | J5: 185 | K5: 204 | M5: =SONDAGEM!B7 -> 0 | N5: =OFFSET(B4,MATCH(M7,A4:A26,0)-1,MATCH(N7,B3:K3,0)-1) -> 6
A6: 20 | B6: 224 | C6: 245 | D6: 267 | E6: 289 | F6: 313 | G6: 337 | H6: 362 | I6: 387 | J6: 414 | K6: 441 | M6: =M5-N6 -> 0 | N6: =VALUE(RIGHT(M5,1)) -> 0
A7: 30 | B7: 469 | C7: 498 | D7: 527 | E7: 557 | F7: 588 | G7: 620 | H7: 653 | I7: 686 | J7: 720 | K7: 755 | M7: =M6 -> 0 | N7: =N6 -> 0
A8: 40 | B8: 790 | C8: 826 | D8: 863 | E8: 900 | F8: 939 | G8: 978 | H8: 1017 | I8: 1058 | J8: 1099 | K8: 1140
A9: 50 | B9: 1183 | C9: 1226 | D9: 1269 | E9: 1314 | F9: 1359 | G9: 1404 | H9: 1450 | I9: 1497 | J9: 1545 | K9: 1593
A10: 60 | B10: 1642 | C10: 1692 | D10: 1742 | E10: 1792 | F10: 1844 | G10: 1896 | H10: 1948 | I10: 2002 | J10: 2056 | K10: 2110
A11: 70 | B11: 2165 | C11: 2221 | D11: 2277 | E11: 2334 | F11: 2391 | G11: 2449 | H11: 2507 | I11: 2566 | J11: 2625 | K11: 2685
A12: 80 | B12: 2745 | C12: 2805 | D12: 2866 | E12: 2928 | F12: 2990 | G12: 3052 | H12: 3115 | I12: 3178 | J12: 3241 | K12: 3305
A13: 90 | B13: 3369 | C13: 3433 | D13: 3498 | E13: 3563 | F13: 3629 | G13: 3695 | H13: 3761 | I13: 3827 | J13: 3894 | K13: 3961
A14: 100 | B14: 4028 | C14: 4096 | D14: 4164 | E14: 4232 | F14: 4300 | G14: 4369 | H14: 4438 | I14: 4507 | J14: 4576 | K14: 4646
A15: 110 | B15: 4716 | C15: 4786 | D15: 4856 | E15: 4926 | F15: 4997 | G15: 5068 | H15: 5140 | I15: 5211 | J15: 5283 | K15: 5355
A16: 120 | B16: 5427 | C16: 5499 | D16: 5572 | E16: 5645 | F16: 5718 | G16: 5791 | H16: 5865 | I16: 5939 | J16: 6013 | K16: 6087
A17: 130 | B17: 6162 | C17: 6237 | D17: 6312 | E17: 6387 | F17: 6462 | G17: 6538 | H17: 6614 | I17: 6690 | J17: 6767 | K17: 6843
A18: 140 | B18: 6920 | C18: 6997 | D18: 7074 | E18: 7152 | F18: 7230 | G18: 7307 | H18: 7385 | I18: 7464 | J18: 7542 | K18: 7621
A19: 150 | B19: 7700 | C19: 7779 | D19: 7858 | E19: 7937 | F19: 8017 | G19: 8097 | H19: 8177 | I19: 8257 | J19: 8337 | K19: 8417
... A25: 210 | B25: 12683 | C25: 12770 | D25: 12856 | E25: 12943 | F25: 13030 | G25: 13116 | H25: 13203 | I25: 13290 | J25: 13378 | K25: 13465
A26: 220 | B26: 13552 | C26: 13640 | D26: 13727 | E26: 13815 | F26: 13903 | G26: 13981
B31: 0 | C31: 1 | D31: 2 | E31: 3 | F31: 4 | G31: 5 | H31: 6 | I31: 7 | J31: 8 | K31: 9 | M31: TRIM NEGATIVO | N31: 5 GRAUS NEG
A32: 0 | B32: 6 | C32: 9 | D32: 13 | E32: 17 | F32: 23 | G32: 29 | H32: 36 | I32: 44 | J32: 52 | K32: 62 | M32: SONDAGEM | N32: VOLUME LTS
A33: 10 | B33: 73 | C33: 85 | D33: 98 | E33: 112 | F33: 127 | G33: 143 | H33: 160 | I33: 178 | J33: 197 | K33: 217 | M33: =SONDAGEM!B7 -> 0 | N33: =OFFSET(B32,MATCH(M35,A32:A54,0)-1,MATCH(N35,B31:K31,0)-1) -> 6
A34: 20 | B34: 238 | C34: 259 | D34: 281 | E34: 305 | F34: 328 | G34: 353 | H34: 379 | I34: 405 | J34: 432 | K34: 460 | M34: =M33-N34 -> 0 | N34: =VALUE(RIGHT(M33,1)) -> 0
A35: 30 | B35: 488 | C35: 518 | D35: 548 | E35: 579 | F35: 610 | G35: 643 | H35: 676 | I35: 710 | J35: 744 | K35: 779 | M35: =M34 -> 0 | N35: =N34 -> 0
A36: 40 | B36: 815 | C36: 852 | D36: 889 | E36: 928 | F36: 966 | G36: 1006 | H36: 1046 | I36: 1087 | J36: 1128 | K36: 1170
A37: 50 | B37: 1213 | C37: 1257 | D37: 1301 | E37: 1346 | F37: 1391 | G37: 1438 | H37: 1484 | I37: 1532 | J37: 1580 | K37: 1629
A38: 60 | B38: 1678 | C38: 1728 | D38: 1779 | E38: 1830 | F38: 1882 | G38: 1934 | H38: 1987 | I38: 2041 | J38: 2095 | K38: 2150
A39: 70 | B39: 2206 | C39: 2262 | D39: 2319 | E39: 2376 | F39: 2434 | G39: 2492 | H39: 2550 | I39: 2610 | J39: 2669 | K39: 2730
A40: 80 | B40: 2790 | C40: 2851 | D40: 2913 | E40: 2974 | F40: 3037 | G40: 3099 | H40: 3162 | I40: 3226 | J40: 3290 | K40: 3354
A41: 90 | B41: 3418 | C41: 3483 | D41: 3548 | E41: 3614 | F41: 3680 | G41: 3746 | H41: 3812 | I41: 3879 | J41: 3946 | K41: 4013
A42: 100 | B42: 4081 | C42: 4148 | D42: 4216 | E42: 4285 | F42: 4353 | G42: 4422 | H42: 4491 | I42: 4561 | J42: 4630 | K42: 4700
A43: 110 | B43: 4770 | C43: 4840 | D43: 4911 | E43: 4982 | F43: 5053 | G43: 5124 | H43: 5195 | I43: 5267 | J43: 5339 | K43: 5411
A44: 120 | B44: 5484 | C44: 5556 | D44: 5629 | E44: 5702 | F44: 5775 | G44: 5849 | H44: 5923 | I44: 5997 | J44: 6071 | K44: 6146
A45: 130 | B45: 6220 | C45: 6295 | D45: 6371 | E45: 6446 | F45: 6522 | G45: 6598 | H45: 6674 | I45: 6750 | J45: 6827 | K45: 6904
A46: 140 | B46: 6981 | C46: 7058 | D46: 7135 | E46: 7213 | F46: 7291 | G46: 7369 | H46: 7447 | I46: 7526 | J46: 7604 | K46: 7683
A47: 150 | B47: 7762 | C47: 7842 | D47: 7921 | E47: 8000 | F47: 8080 | G47: 8160 | H47: 8240 | I47: 8320 | J47: 8401 | K47: 8481
... A53: 210 | B53: 12753 | C53: 12840 | D53: 12926 | E53: 13013 | F53: 13100 | G53: 13187 | H53: 13274 | I53: 13361 | J53: 13448 | K53: 13535
A54: 220 | B54: 13623 | C54: 13710 | D54: 13798 | E54: 13886 | F54: 13956 | G54: 13981
B58: 0 | C58: 1 | D58: 2 | E58: 3 | F58: 4 | G58: 5 | H58: 6 | I58: 7 | J58: 8 | K58: 9 | M58: TRIM | N58: 5 GRAUS POS
A59: 0 | B59: 6 | C59: 9 | D59: 12 | E59: 16 | F59: 20 | G59: 26 | H59: 32 | I59: 39 | J59: 46 | K59: 55 | M59: SONDAGEM | N59: VOLUME LTS
...

Sheet TK6 BE
B3: 0 | C3: 1 | D3: 2 | E3: 3 | F3: 4 | G3: 5 | H3: 6 | I3: 7 | J3: 8 | K3: 9 | M3: TRIM NEGATIVO | N3: 5 GRAUS NEG
A4: 0 | B4: 8 | C4: 11 | D4: 15 | E4: 20 | F4: 26 | G4: 32 | H4: 38 | I4: 45 | J4: 53 | K4: 61 | M4: SONDAGEM | N4: VOLUME LTS
A5: 10 | B5: 69 | C5: 79 | D5: 88 | E5: 98 | F5: 109 | G5: 120 | H5: 131 | I5: 143 | J5: 156 | K5: 168 | M5: =SONDAGEM!B8 -> 0 | N5: =OFFSET(B4,MATCH(M7,A4:A26,0)-1,MATCH(N7,B3:K3,0)-1) -> 8
A6: 20 | B6: 182 | C6: 195 | D6: 210 | E6: 224 | F6: 239 | G6: 255 | H6: 271 | I6: 287 | J6: 305 | K6: 322 | M6: =M5-N6 -> 0 | N6: =VALUE(RIGHT(M5,1)) -> 0
A7: 30 | B7: 340 | C7: 359 | D7: 379 | E7: 399 | F7: 419 | G7: 441 | H7: 462 | I7: 485 | J7: 508 | K7: 532 | M7: =M6 -> 0 | N7: =N6 -> 0
A8: 40 | B8: 557 | C8: 582 | D8: 608 | E8: 635 | F8: 662 | G8: 690 | H8: 719 | I8: 748 | J8: 778 | K8: 809
A9: 50 | B9: 841 | C9: 873 | D9: 906 | E9: 939 | F9: 973 | G9: 1008 | H9: 1044 | I9: 1080 | J9: 1117 | K9: 1154
A10: 60 | B10: 1192 | C10: 1231 | D10: 1270 | E10: 1310 | F10: 1351 | G10: 1392 | H10: 1434 | I10: 1476 | J10: 1520 | K10: 1563
A11: 70 | B11: 1608 | C11: 1652 | D11: 1698 | E11: 1744 | F11: 1790 | G11: 1837 | H11: 1885 | I11: 1933 | J11: 1981 | K11: 2030
A12: 80 | B12: 2080 | C12: 2130 | D12: 2180 | E12: 2231 | F12: 2282 | G12: 2333 | H12: 2385 | I12: 2437 | J12: 2490 | K12: 2543
A13: 90 | B13: 2597 | C13: 2650 | D13: 2704 | E13: 2759 | F13: 2813 | G13: 2868 | H13: 2924 | I13: 2979 | J13: 3035 | K13: 3092
A14: 100 | B14: 3148 | C14: 3205 | D14: 3262 | E14: 3319 | F14: 3377 | G14: 3435 | H14: 3493 | I14: 3551 | J14: 3610 | K14: 3669
A15: 110 | B15: 3728 | C15: 3787 | D15: 3847 | E15: 3907 | F15: 3967 | G15: 4027 | H15: 4088 | I15: 4148 | J15: 4209 | K15: 4271
A16: 120 | B16: 4332 | C16: 4394 | D16: 4456 | E16: 4518 | F16: 4580 | G16: 4643 | H16: 4706 | I16: 4769 | J16: 4832 | K16: 4896
A17: 130 | B17: 4960 | C17: 5024 | D17: 5088 | E17: 5153 | F17: 5217 | G17: 5282 | H17: 5348 | I17: 5413 | J17: 5479 | K17: 5545
A18: 140 | B18: 5611 | C18: 5677 | D18: 5744 | E18: 5811 | F18: 5877 | G18: 5945 | H18: 6012 | I18: 6080 | J18: 6147 | K18: 6215
A19: 150 | B19: 6283 | C19: 6352 | D19: 6420 | E19: 6489 | F19: 6558 | G19: 6627 | H19: 6696 | I19: 6765 | J19: 6835 | K19: 6905
... A25: 210 | B25: 10624 | C25: 10700 | D25: 10776 | E25: 10852 | F25: 10928 | G25: 11004 | H25: 11080 | I25: 11156 | J25: 11233 | K25: 11309
A26: 220 | B26: 11386 | C26: 11463 | D26: 11540 | E26: 11617 | F26: 11694
B31: 0 | C31: 1 | D31: 2 | E31: 3 | F31: 4 | G31: 5 | H31: 6 | I31: 7 | J31: 8 | K31: 9 | M31: TRIM NEGATIVO | N31: 5 GRAUS NEG
A32: 0 | B32: 8 | C32: 12 | D32: 17 | E32: 22 | F32: 27 | G32: 33 | H32: 40 | I32: 47 | J32: 55 | K32: 63 | M32: SONDAGEM | N32: VOLUME LTS
A33: 10 | B33: 72 | C33: 81 | D33: 91 | E33: 101 | F33: 112 | G33: 123 | H33: 135 | I33: 147 | J33: 160 | K33: 173 | M33: =SONDAGEM!B8 -> 0 | N33: =OFFSET(B32,MATCH(M35,A32:A54,0)-1,MATCH(N35,B31:K31,0)-1) -> 8
A34: 20 | B34: 186 | C34: 200 | D34: 214 | E34: 229 | F34: 244 | G34: 260 | H34: 276 | I34: 293 | J34: 311 | K34: 328 | M34: =M33-N34 -> 0 | N34: =VALUE(RIGHT(M33,1)) -> 0
A35: 30 | B35: 347 | C35: 366 | D35: 386 | E35: 406 | F35: 427 | G35: 449 | H35: 471 | I35: 494 | J35: 518 | K35: 543 | M35: =M34 -> 0 | N35: =N34 -> 0
A36: 40 | B36: 568 | C36: 593 | D36: 620 | E36: 647 | F36: 675 | G36: 704 | H36: 733 | I36: 763 | J36: 794 | K36: 825
A37: 50 | B37: 857 | C37: 890 | D37: 923 | E37: 957 | F37: 992 | G37: 1027 | H37: 1063 | I37: 1100 | J37: 1137 | K37: 1175
A38: 60 | B38: 1214 | C38: 1253 | D38: 1293 | E38: 1333 | F38: 1374 | G38: 1416 | H38: 1458 | I38: 1501 | J38: 1545 | K38: 1589
A39: 70 | B39: 1634 | C39: 1679 | D39: 1725 | E39: 1772 | F39: 1819 | G39: 1866 | H39: 1914 | I39: 1963 | J39: 2011 | K39: 2061
A40: 80 | B40: 2111 | C40: 2161 | D40: 2212 | E40: 2263 | F40: 2314 | G40: 2366 | H40: 2419 | I40: 2471 | J40: 2524 | K40: 2578
A41: 90 | B41: 2631 | C41: 2685 | D41: 2740 | E41: 2795 | F41: 2850 | G41: 2905 | H41: 2961 | I41: 3017 | J41: 3073 | K41: 3129
A42: 100 | B42: 3186 | C42: 3243 | D42: 3300 | E42: 3358 | F42: 3416 | G42: 3474 | H42: 3532 | I42: 3591 | J42: 3650 | K42: 3709
A43: 110 | B43: 3768 | C43: 3828 | D43: 3887 | E43: 3947 | F43: 4008 | G43: 4068 | H43: 4129 | I43: 4190 | J43: 4251 | K43: 4312
A44: 120 | B44: 4374 | C44: 4436 | D44: 4498 | E44: 4561 | F44: 4623 | G44: 4686 | H44: 4749 | I44: 4812 | J44: 4876 | K44: 4940
A45: 130 | B45: 5004 | C45: 5068 | D45: 5133 | E45: 5197 | F45: 5262 | G45: 5328 | H45: 5393 | I45: 5459 | J45: 5525 | K45: 5591
A46: 140 | B46: 5657 | C46: 5724 | D46: 5790 | E46: 5857 | F46: 5924 | G46: 5992 | H46: 6059 | I46: 6127 | J46: 6195 | K46: 6263
A47: 150 | B47: 6332 | C47: 6400 | D47: 6469 | E47: 6538 | F47: 6607 | G47: 6676 | H47: 6745 | I47: 6815 | J47: 6884 | K47: 6954
... A53: 210 | B53: 10679 | C53: 10755 | D53: 10831 | E53: 10907 | F53: 10983 | G53: 11060 | H53: 11136 | I53: 11212 | J53: 11289 | K53: 11365
A54: 220 | B54: 11442 | C54: 11519 | D54: 11596 | E54: 11663 | F54: 11694
B60: 0 | C60: 1 | D60: 2 | E60: 3 | F60: 4 | G60: 5 | H60: 6 | I60: 7 | J60: 8 | K60: 9 | M60: TRIM NEGATIVO | N60: 5 GRAUS NEG
A61: 0 | B61: 7 | C61: 10 | D61: 14 | E61: 19 | F61: 24 | G61: 30 | H61: 36 | I61: 43 | J61: 50 | K61: 58 | M61: SONDAGEM | N61: VOLUME LTS
...
